Workbook
Name PlayersList: Jugadores!$B$2:$B$61

Sheet Ayuda
A1: Guía rápida (sin errores de reparación)
A3: 1) Alta de jugadores
A4: Hoja 'Jugadores': escribe los nombres en la columna B (desde B2).
A5: 2) Registrar partidos
A6: Hoja 'Partidos': rellena Fecha, Tipo (Liga/Eliminatoria), jugadores A1/A2/B1/B2 y los juegos por set. Las columnas Sets/Games/Diff/Bonus se calculan solas.
A7: 3) Ranking
A8: Hoja 'Ranking': se actualiza automáticamente con PJ, V, D, Dif, Bonus y Puntos. La columna Pos evita empates invisibles.
A9: 4) Consulta jugador
A10: Hoja 'Consulta': selecciona jugador en B3 y copia el texto en H6 para WhatsApp (individual).
A11: 5) Previa de partido
A12: Hoja 'Previa': selecciona 4 jugadores y copia el texto de A16 para enviar la previa al grupo.
A13: 6) Ver últimos partidos (sin hoja 'Ultimos')
A14: En la hoja 'Partidos' usa el filtro (fila 1): filtra A1/A2/B1/B2 por un jugador y ordena por ID (columna A) de mayor a menor. Así ves los últimos partidos sin fórmulas adicionales.

Sheet Jugadores
A1: ID | B1: Nombre
A2: 1 | B2: Javier suarez
A3: 2 | B3: Imobach González
A4: 3 | B4: José López
A5: 4 | B5: César Morales
A6: 5 | B6: Carmelo Rosario
A7: 6 | B7: Israel Suárez
A8: 7 | B8: Cristo Marrero
A9: 8 | B9: Alberto Pulido
A10: 9 | B10: Wilfredo Santana
A11: 10 | B11: Javier Bonilla
A12: 11 | B12: José Fernando
A13: 12 | B13: Guillermo Medina
... A17: 16 | B17: Yeray Armas
A18: 17
A19: 18
A20: 19
A21: 20
A22: 21
A23: 22
A24: 23
A25: 24
A26: 25
A27: 26
A28: 27
A29: 28
... A61: 60

Sheet Partidos
A1: ID | B1: Fecha | C1: Tipo | D1: A1 | E1: A2 | F1: B1 | G1: B2 | H1: S1_A | I1: S1_B | J1: S2_A | K1: S2_B | L1: S3_A | M1: S3_B | N1: Sets_A | O1: Sets_B | P1: Winner(A/B) | Q1: Games_A | R1: Games_B | S1: Diff(A-B) | T1: Bonus_A | U1: Bonus_B | V1: IncluyeJugador | W1: Config | Z1: Filtro jugador | AA1: Temporada | AB1: OK_Temp
A2: 1 | B2: 45771 | C2: Liga | D2: Javier Bonilla | E2: Imobach González | F2: Wilfredo Santana | G2: Nacho Navidad | H2: 7 | I2: 5 | J2: 7 | K2: 6 | N2: =IF(OR(H2="",I2="",J2="",K2=""),"",(IF(H2>I2,1,0)+IF(J2>K2,1,0)+IF(AND(L2<>"",M2<>""),IF(L2>M2,1,0),0))) -> 2 | O2: =IF(N2="","",(IF(H2<I2,1,0)+IF(J2<K2,1,0)+IF(AND(L2<>"",M2<>""),IF(L2<M2,1,0),0))) -> 0 | P2: =IF(N2="","",IF(N2>O2,"A","B")) -> A | Q2: =IF(N2="","",H2+J2+IF(L2="",0,L2)) -> 14 | R2: =IF(N2="","",I2+K2+IF(M2="",0,M2)) -> 11 | S2: =IF(N2="","",Q2-R2) -> 3 | T2: =IF(OR(C2<>$X$2,P2=""),"",MIN(MAX(0,S2)*$X$5,$X$6)) -> 0.06 | U2: =IF(OR(C2<>$X$2,P2=""),"",MIN(MAX(0,-S2)*$X$5,$X$6)) -> 0 | V2: =IF($Z$2="","",OR($D2=$Z$2,$E2=$Z$2,$F2=$Z$2,$G2=$Z$2)) -> FALSE | W2: LigaLabel | X2: Liga | Z2: Yeray Armas | AA2: =IF($B2="","",YEAR($B2)) -> 2025 | AB2: =IF($Z$5="Todas",TRUE,$AA2=$Z$5) -> TRUE
A3: 2 | B3: 45772 | C3: Liga | D3: Nacho Navidad | E3: Israel Suárez | F3: Imobach González | G3: Javier Bonilla | H3: 2 | I3: 6 | J3: 6 | K3: 3 | L3: 5 | M3: 7 | N3: =IF(OR(H3="",I3="",J3="",K3=""),"",(IF(H3>I3,1,0)+IF(J3>K3,1,0)+IF(AND(L3<>"",M3<>""),IF(L3>M3,1,0),0))) -> 1 | O3: =IF(N3="","",(IF(H3<I3,1,0)+IF(J3<K3,1,0)+IF(AND(L3<>"",M3<>""),IF(L3<M3,1,0),0))) -> 2 | P3: =IF(N3="","",IF(N3>O3,"A","B")) -> B | Q3: =IF(N3="","",H3+J3+IF(L3="",0,L3)) -> 13 | R3: =IF(N3="","",I3+K3+IF(M3="",0,M3)) -> 16 | S3: =IF(N3="","",Q3-R3) -> -3 | T3: =IF(OR(C3<>$X$2,P3=""),"",MIN(MAX(0,S3)*$X$5,$X$6)) -> 0 | U3: =IF(OR(C3<>$X$2,P3=""),"",MIN(MAX(0,-S3)*$X$5,$X$6)) -> 0.06 | V3: =IF($Z$2="","",OR($D3=$Z$2,$E3=$Z$2,$F3=$Z$2,$G3=$Z$2)) -> FALSE | W3: WinPts | X3: 2 | AA3: =IF($B3="","",YEAR($B3)) -> 2025 | AB3: =IF($Z$5="Todas",TRUE,$AA3=$Z$5) -> TRUE
A4: 3 | B4: 45776 | C4: Liga | D4: Carmelo Rosario | E4: Guillermo Medina | F4: Nacho Navidad | G4: Israel Suárez | H4: 6 | I4: 3 | J4: 5 | K4: 7 | L4: 0 | M4: 6 | N4: =IF(OR(H4="",I4="",J4="",K4=""),"",(IF(H4>I4,1,0)+IF(J4>K4,1,0)+IF(AND(L4<>"",M4<>""),IF(L4>M4,1,0),0))) -> 1 | O4: =IF(N4="","",(IF(H4<I4,1,0)+IF(J4<K4,1,0)+IF(AND(L4<>"",M4<>""),IF(L4<M4,1,0),0))) -> 2 | P4: =IF(N4="","",IF(N4>O4,"A","B")) -> B | Q4: =IF(N4="","",H4+J4+IF(L4="",0,L4)) -> 11 | R4: =IF(N4="","",I4+K4+IF(M4="",0,M4)) -> 16 | S4: =IF(N4="","",Q4-R4) -> -5 | T4: =IF(OR(C4<>$X$2,P4=""),"",MIN(MAX(0,S4)*$X$5,$X$6)) -> 0 | U4: =IF(OR(C4<>$X$2,P4=""),"",MIN(MAX(0,-S4)*$X$5,$X$6)) -> 0.1 | V4: =IF($Z$2="","",OR($D4=$Z$2,$E4=$Z$2,$F4=$Z$2,$G4=$Z$2)) -> FALSE | W4: LossPts | X4: 0 | Z4: Temporada (filtro) | AA4: =IF($B4="","",YEAR($B4)) -> 2025 | AB4: =IF($Z$5="Todas",TRUE,$AA4=$Z$5) -> TRUE
A5: 4 | B5: 45776 | C5: Liga | D5: Javier Bonilla | E5: Imobach González | F5: Cristo Marrero | G5: César Morales | H5: 7 | I5: 5 | J5: 6 | K5: 4 | N5: =IF(OR(H5="",I5="",J5="",K5=""),"",(IF(H5>I5,1,0)+IF(J5>K5,1,0)+IF(AND(L5<>"",M5<>""),IF(L5>M5,1,0),0))) -> 2 | O5: =IF(N5="","",(IF(H5<I5,1,0)+IF(J5<K5,1,0)+IF(AND(L5<>"",M5<>""),IF(L5<M5,1,0),0))) -> 0 | P5: =IF(N5="","",IF(N5>O5,"A","B")) -> A | Q5: =IF(N5="","",H5+J5+IF(L5="",0,L5)) -> 13 | R5: =IF(N5="","",I5+K5+IF(M5="",0,M5)) -> 9 | S5: =IF(N5="","",Q5-R5) -> 4 | T5: =IF(OR(C5<>$X$2,P5=""),"",MIN(MAX(0,S5)*$X$5,$X$6)) -> 0.08 | U5: =IF(OR(C5<>$X$2,P5=""),"",MIN(MAX(0,-S5)*$X$5,$X$6)) -> 0 | V5: =IF($Z$2="","",OR($D5=$Z$2,$E5=$Z$2,$F5=$Z$2,$G5=$Z$2)) -> FALSE | W5: BonusCoef | X5: 0.02 | Z5: 2025 | AA5: =IF($B5="","",YEAR($B5)) -> 2025 | AB5: =IF($Z$5="Todas",TRUE,$AA5=$Z$5) -> TRUE
A6: 5 | B6: 45779 | C6: Liga | D6: Cristo Marrero | E6: Carmelo Rosario | F6: Javier Bonilla | G6: Javier suarez | H6: 6 | I6: 4 | J6: 6 | K6: 3 | N6: =IF(OR(H6="",I6="",J6="",K6=""),"",(IF(H6>I6,1,0)+IF(J6>K6,1,0)+IF(AND(L6<>"",M6<>""),IF(L6>M6,1,0),0))) -> 2 | O6: =IF(N6="","",(IF(H6<I6,1,0)+IF(J6<K6,1,0)+IF(AND(L6<>"",M6<>""),IF(L6<M6,1,0),0))) -> 0 | P6: =IF(N6="","",IF(N6>O6,"A","B")) -> A | Q6: =IF(N6="","",H6+J6+IF(L6="",0,L6)) -> 12 | R6: =IF(N6="","",I6+K6+IF(M6="",0,M6)) -> 7 | S6: =IF(N6="","",Q6-R6) -> 5 | T6: =IF(OR(C6<>$X$2,P6=""),"",MIN(MAX(0,S6)*$X$5,$X$6)) -> 0.1 | U6: =IF(OR(C6<>$X$2,P6=""),"",MIN(MAX(0,-S6)*$X$5,$X$6)) -> 0 | V6: =IF($Z$2="","",OR($D6=$Z$2,$E6=$Z$2,$F6=$Z$2,$G6=$Z$2)) -> FALSE | W6: BonusCap | X6: 0.5 | AA6: =IF($B6="","",YEAR($B6)) -> 2025 | AB6: =IF($Z$5="Todas",TRUE,$AA6=$Z$5) -> TRUE
A7: 6 | B7: 45783 | C7: Liga | D7: Yeray Armas | E7: José López | F7: Nacho Navidad | G7: Javier Bonilla | H7: 6 | I7: 2 | J7: 6 | K7: 3 | N7: =IF(OR(H7="",I7="",J7="",K7=""),"",(IF(H7>I7,1,0)+IF(J7>K7,1,0)+IF(AND(L7<>"",M7<>""),IF(L7>M7,1,0),0))) -> 2 | O7: =IF(N7="","",(IF(H7<I7,1,0)+IF(J7<K7,1,0)+IF(AND(L7<>"",M7<>""),IF(L7<M7,1,0),0))) -> 0 | P7: =IF(N7="","",IF(N7>O7,"A","B")) -> A | Q7: =IF(N7="","",H7+J7+IF(L7="",0,L7)) -> 12 | R7: =IF(N7="","",I7+K7+IF(M7="",0,M7)) -> 5 | S7: =IF(N7="","",Q7-R7) -> 7 | T7: =IF(OR(C7<>$X$2,P7=""),"",MIN(MAX(0,S7)*$X$5,$X$6)) -> 0.14 | U7: =IF(OR(C7<>$X$2,P7=""),"",MIN(MAX(0,-S7)*$X$5,$X$6)) -> 0 | V7: =IF($Z$2="","",OR($D7=$Z$2,$E7=$Z$2,$F7=$Z$2,$G7=$Z$2)) -> TRUE | AA7: =IF($B7="","",YEAR($B7)) -> 2025 | AB7: =IF($Z$5="Todas",TRUE,$AA7=$Z$5) -> TRUE
A8: 7 | B8: 45784 | C8: Liga | D8: Yeray Armas | E8: Cristo Marrero | F8: Carmelo Rosario | G8: César Morales | H8: 2 | I8: 6 | J8: 3 | K8: 6 | N8: =IF(OR(H8="",I8="",J8="",K8=""),"",(IF(H8>I8,1,0)+IF(J8>K8,1,0)+IF(AND(L8<>"",M8<>""),IF(L8>M8,1,0),0))) -> 0 | O8: =IF(N8="","",(IF(H8<I8,1,0)+IF(J8<K8,1,0)+IF(AND(L8<>"",M8<>""),IF(L8<M8,1,0),0))) -> 2 | P8: =IF(N8="","",IF(N8>O8,"A","B")) -> B | Q8: =IF(N8="","",H8+J8+IF(L8="",0,L8)) -> 5 | R8: =IF(N8="","",I8+K8+IF(M8="",0,M8)) -> 12 | S8: =IF(N8="","",Q8-R8) -> -7 | T8: =IF(OR(C8<>$X$2,P8=""),"",MIN(MAX(0,S8)*$X$5,$X$6)) -> 0 | U8: =IF(OR(C8<>$X$2,P8=""),"",MIN(MAX(0,-S8)*$X$5,$X$6)) -> 0.14 | V8: =IF($Z$2="","",OR($D8=$Z$2,$E8=$Z$2,$F8=$Z$2,$G8=$Z$2)) -> TRUE | AA8: =IF($B8="","",YEAR($B8)) -> 2025 | AB8: =IF($Z$5="Todas",TRUE,$AA8=$Z$5) -> TRUE
A9: 8 | B9: 45785 | C9: Liga | D9: Carmelo Rosario | E9: Alberto Nunes | F9: Wilfredo Santana | G9: Imobach González | H9: 7 | I9: 5 | J9: 4 | K9: 6 | L9: 6 | M9: 3 | N9: =IF(OR(H9="",I9="",J9="",K9=""),"",(IF(H9>I9,1,0)+IF(J9>K9,1,0)+IF(AND(L9<>"",M9<>""),IF(L9>M9,1,0),0))) -> 2 | O9: =IF(N9="","",(IF(H9<I9,1,0)+IF(J9<K9,1,0)+IF(AND(L9<>"",M9<>""),IF(L9<M9,1,0),0))) -> 1 | P9: =IF(N9="","",IF(N9>O9,"A","B")) -> A | Q9: =IF(N9="","",H9+J9+IF(L9="",0,L9)) -> 17 | R9: =IF(N9="","",I9+K9+IF(M9="",0,M9)) -> 14 | S9: =IF(N9="","",Q9-R9) -> 3 | T9: =IF(OR(C9<>$X$2,P9=""),"",MIN(MAX(0,S9)*$X$5,$X$6)) -> 0.06 | U9: =IF(OR(C9<>$X$2,P9=""),"",MIN(MAX(0,-S9)*$X$5,$X$6)) -> 0 | V9: =IF($Z$2="","",OR($D9=$Z$2,$E9=$Z$2,$F9=$Z$2,$G9=$Z$2)) -> FALSE | AA9: =IF($B9="","",YEAR($B9)) -> 2025 | AB9: =IF($Z$5="Todas",TRUE,$AA9=$Z$5) -> TRUE
A10: 9 | B10: 45786 | C10: Liga | D10: Yeray Armas | E10: Imobach González | F10: Carmelo Rosario | G10: Nacho Navidad | H10: 3 | I10: 6 | J10: 7 | K10: 6 | L10: 3 | M10: 6 | N10: =IF(OR(H10="",I10="",J10="",K10=""),"",(IF(H10>I10,1,0)+IF(J10>K10,1,0)+IF(AND(L10<>"",M10<>""),IF(L10>M10,1,0),0))) -> 1 | O10: =IF(N10="","",(IF(H10<I10,1,0)+IF(J10<K10,1,0)+IF(AND(L10<>"",M10<>""),IF(L10<M10,1,0),0))) -> 2 | P10: =IF(N10="","",IF(N10>O10,"A","B")) -> B | Q10: =IF(N10="","",H10+J10+IF(L10="",0,L10)) -> 13 | R10: =IF(N10="","",I10+K10+IF(M10="",0,M10)) -> 18 | S10: =IF(N10="","",Q10-R10) -> -5 | T10: =IF(OR(C10<>$X$2,P10=""),"",MIN(MAX(0,S10)*$X$5,$X$6)) -> 0 | U10: =IF(OR(C10<>$X$2,P10=""),"",MIN(MAX(0,-S10)*$X$5,$X$6)) -> 0.1 | V10: =IF($Z$2="","",OR($D10=$Z$2,$E10=$Z$2,$F10=$Z$2,$G10=$Z$2)) -> TRUE | AA10: =IF($B10="","",YEAR($B10)) -> 2025 | AB10: =IF($Z$5="Todas",TRUE,$AA10=$Z$5) -> TRUE
A11: 10 | B11: 45791 | C11: Liga | D11: Israel Suárez | E11: Imobach González | F11: Nacho Navidad | G11: Yeray Armas | H11: 6 | I11: 1 | J11: 6 | K11: 1 | N11: =IF(OR(H11="",I11="",J11="",K11=""),"",(IF(H11>I11,1,0)+IF(J11>K11,1,0)+IF(AND(L11<>"",M11<>""),IF(L11>M11,1,0),0))) -> 2 | O11: =IF(N11="","",(IF(H11<I11,1,0)+IF(J11<K11,1,0)+IF(AND(L11<>"",M11<>""),IF(L11<M11,1,0),0))) -> 0 | P11: =IF(N11="","",IF(N11>O11,"A","B")) -> A | Q11: =IF(N11="","",H11+J11+IF(L11="",0,L11)) -> 12 | R11: =IF(N11="","",I11+K11+IF(M11="",0,M11)) -> 2 | S11: =IF(N11="","",Q11-R11) -> 10 | T11: =IF(OR(C11<>$X$2,P11=""),"",MIN(MAX(0,S11)*$X$5,$X$6)) -> 0.2 | U11: =IF(OR(C11<>$X$2,P11=""),"",MIN(MAX(0,-S11)*$X$5,$X$6)) -> 0 | V11: =IF($Z$2="","",OR($D11=$Z$2,$E11=$Z$2,$F11=$Z$2,$G11=$Z$2)) -> TRUE | AA11: =IF($B11="","",YEAR($B11)) -> 2025 | AB11: =IF($Z$5="Todas",TRUE,$AA11=$Z$5) -> TRUE
A12: 11 | B12: 45791 | C12: Liga | D12: Israel Suárez | E12: Nacho Navidad | F12: Imobach González | G12: Yeray Armas | H12: 7 | I12: 5 | J12: 6 | K12: 2 | N12: =IF(OR(H12="",I12="",J12="",K12=""),"",(IF(H12>I12,1,0)+IF(J12>K12,1,0)+IF(AND(L12<>"",M12<>""),IF(L12>M12,1,0),0))) -> 2 | O12: =IF(N12="","",(IF(H12<I12,1,0)+IF(J12<K12,1,0)+IF(AND(L12<>"",M12<>""),IF(L12<M12,1,0),0))) -> 0 | P12: =IF(N12="","",IF(N12>O12,"A","B")) -> A | Q12: =IF(N12="","",H12+J12+IF(L12="",0,L12)) -> 13 | R12: =IF(N12="","",I12+K12+IF(M12="",0,M12)) -> 7 | S12: =IF(N12="","",Q12-R12) -> 6 | T12: =IF(OR(C12<>$X$2,P12=""),"",MIN(MAX(0,S12)*$X$5,$X$6)) -> 0.12 | U12: =IF(OR(C12<>$X$2,P12=""),"",MIN(MAX(0,-S12)*$X$5,$X$6)) -> 0 | V12: =IF($Z$2="","",OR($D12=$Z$2,$E12=$Z$2,$F12=$Z$2,$G12=$Z$2)) -> TRUE | AA12: =IF($B12="","",YEAR($B12)) -> 2025 | AB12: =IF($Z$5="Todas",TRUE,$AA12=$Z$5) -> TRUE
A13: 12 | B13: 45792 | C13: Liga | D13: Imobach González | E13: Alberto Nunes | F13: Cristo Marrero | G13: Guillermo Medina | H13: 3 | I13: 6 | J13: 2 | K13: 6 | N13: =IF(OR(H13="",I13="",J13="",K13=""),"",(IF(H13>I13,1,0)+IF(J13>K13,1,0)+IF(AND(L13<>"",M13<>""),IF(L13>M13,1,0),0))) -> 0 | O13: =IF(N13="","",(IF(H13<I13,1,0)+IF(J13<K13,1,0)+IF(AND(L13<>"",M13<>""),IF(L13<M13,1,0),0))) -> 2 | P13: =IF(N13="","",IF(N13>O13,"A","B")) -> B | Q13: =IF(N13="","",H13+J13+IF(L13="",0,L13)) -> 5 | R13: =IF(N13="","",I13+K13+IF(M13="",0,M13)) -> 12 | S13: =IF(N13="","",Q13-R13) -> -7 | T13: =IF(OR(C13<>$X$2,P13=""),"",MIN(MAX(0,S13)*$X$5,$X$6)) -> 0 | U13: =IF(OR(C13<>$X$2,P13=""),"",MIN(MAX(0,-S13)*$X$5,$X$6)) -> 0.14 | V13: =IF($Z$2="","",OR($D13=$Z$2,$E13=$Z$2,$F13=$Z$2,$G13=$Z$2)) -> FALSE | AA13: =IF($B13="","",YEAR($B13)) -> 2025 | AB13: =IF($Z$5="Todas",TRUE,$AA13=$Z$5) -> TRUE
A14: 13 | B14: 45797 | C14: Liga | D14: Javier Bonilla | E14: Javier suarez | F14: Carmelo Rosario | G14: Nacho Navidad | H14: 6 | I14: 2 | J14: 6 | K14: 7 | L14: 6 | M14: 3 | N14: =IF(OR(H14="",I14="",J14="",K14=""),"",(IF(H14>I14,1,0)+IF(J14>K14,1,0)+IF(AND(L14<>"",M14<>""),IF(L14>M14,1,0),0))) -> 2 | O14: =IF(N14="","",(IF(H14<I14,1,0)+IF(J14<K14,1,0)+IF(AND(L14<>"",M14<>""),IF(L14<M14,1,0),0))) -> 1 | P14: =IF(N14="","",IF(N14>O14,"A","B")) -> A | Q14: =IF(N14="","",H14+J14+IF(L14="",0,L14)) -> 18 | R14: =IF(N14="","",I14+K14+IF(M14="",0,M14)) -> 12 | S14: =IF(N14="","",Q14-R14) -> 6 | T14: =IF(OR(C14<>$X$2,P14=""),"",MIN(MAX(0,S14)*$X$5,$X$6)) -> 0.12 | U14: =IF(OR(C14<>$X$2,P14=""),"",MIN(MAX(0,-S14)*$X$5,$X$6)) -> 0 | V14: =IF($Z$2="","",OR($D14=$Z$2,$E14=$Z$2,$F14=$Z$2,$G14=$Z$2)) -> FALSE | AA14: =IF($B14="","",YEAR($B14)) -> 2025 | AB14: =IF($Z$5="Todas",TRUE,$AA14=$Z$5) -> TRUE
A15: 14 | B15: 45799 | C15: Liga | D15: Alberto Nunes | E15: Guillermo Medina | F15: Carmelo Rosario | G15: César Morales | H15: 2 | I15: 6 | J15: 1 | K15: 6 | N15: =IF(OR(H15="",I15="",J15="",K15=""),"",(IF(H15>I15,1,0)+IF(J15>K15,1,0)+IF(AND(L15<>"",M15<>""),IF(L15>M15,1,0),0))) -> 0 | O15: =IF(N15="","",(IF(H15<I15,1,0)+IF(J15<K15,1,0)+IF(AND(L15<>"",M15<>""),IF(L15<M15,1,0),0))) -> 2 | P15: =IF(N15="","",IF(N15>O15,"A","B")) -> B | Q15: =IF(N15="","",H15+J15+IF(L15="",0,L15)) -> 3 | R15: =IF(N15="","",I15+K15+IF(M15="",0,M15)) -> 12 | S15: =IF(N15="","",Q15-R15) -> -9 | T15: =IF(OR(C15<>$X$2,P15=""),"",MIN(MAX(0,S15)*$X$5,$X$6)) -> 0 | U15: =IF(OR(C15<>$X$2,P15=""),"",MIN(MAX(0,-S15)*$X$5,$X$6)) -> 0.18 | V15: =IF($Z$2="","",OR($D15=$Z$2,$E15=$Z$2,$F15=$Z$2,$G15=$Z$2)) -> FALSE | AA15: =IF($B15="","",YEAR($B15)) -> 2025 | AB15: =IF($Z$5="Todas",TRUE,$AA15=$Z$5) -> TRUE
A16: 15 | B16: 45799 | C16: Liga | D16: Carmelo Rosario | E16: Imobach González | F16: Javier Bonilla | G16: José López | H16: 6 | I16: 7 | J16: 0 | K16: 6 | N16: =IF(OR(H16="",I16="",J16="",K16=""),"",(IF(H16>I16,1,0)+IF(J16>K16,1,0)+IF(AND(L16<>"",M16<>""),IF(L16>M16,1,0),0))) -> 0 | O16: =IF(N16="","",(IF(H16<I16,1,0)+IF(J16<K16,1,0)+IF(AND(L16<>"",M16<>""),IF(L16<M16,1,0),0))) -> 2 | P16: =IF(N16="","",IF(N16>O16,"A","B")) -> B | Q16: =IF(N16="","",H16+J16+IF(L16="",0,L16)) -> 6 | R16: =IF(N16="","",I16+K16+IF(M16="",0,M16)) -> 13 | S16: =IF(N16="","",Q16-R16) -> -7 | T16: =IF(OR(C16<>$X$2,P16=""),"",MIN(MAX(0,S16)*$X$5,$X$6)) -> 0 | U16: =IF(OR(C16<>$X$2,P16=""),"",MIN(MAX(0,-S16)*$X$5,$X$6)) -> 0.14 | V16: =IF($Z$2="","",OR($D16=$Z$2,$E16=$Z$2,$F16=$Z$2,$G16=$Z$2)) -> FALSE | AA16: =IF($B16="","",YEAR($B16)) -> 2025 | AB16: =IF($Z$5="Todas",TRUE,$AA16=$Z$5) -> TRUE
A17: 16 | B17: 45800 | C17: Liga | D17: Carmelo Rosario | E17: Imobach González | F17: Javier suarez | G17: Nacho Navidad | H17: 6 | I17: 4 | J17: 7 | K17: 6 | N17: =IF(OR(H17="",I17="",J17="",K17=""),"",(IF(H17>I17,1,0)+IF(J17>K17,1,0)+IF(AND(L17<>"",M17<>""),IF(L17>M17,1,0),0))) -> 2 | O17: =IF(N17="","",(IF(H17<I17,1,0)+IF(J17<K17,1,0)+IF(AND(L17<>"",M17<>""),IF(L17<M17,1,0),0))) -> 0 | P17: =IF(N17="","",IF(N17>O17,"A","B")) -> A | Q17: =IF(N17="","",H17+J17+IF(L17="",0,L17)) -> 13 | R17: =IF(N17="","",I17+K17+IF(M17="",0,M17)) -> 10 | S17: =IF(N17="","",Q17-R17) -> 3 | T17: =IF(OR(C17<>$X$2,P17=""),"",MIN(MAX(0,S17)*$X$5,$X$6)) -> 0.06 | U17: =IF(OR(C17<>$X$2,P17=""),"",MIN(MAX(0,-S17)*$X$5,$X$6)) -> 0 | V17: =IF($Z$2="","",OR($D17=$Z$2,$E17=$Z$2,$F17=$Z$2,$G17=$Z$2)) -> FALSE | AA17: =IF($B17="","",YEAR($B17)) -> 2025 | AB17: =IF($Z$5="Todas",TRUE,$AA17=$Z$5) -> TRUE
A18: 17 | B18: 45804 | C18: Liga | D18: Israel Suárez | E18: Nacho Navidad | F18: Eva Pulido | G18: José López | H18: 4 | I18: 6 | J18: 4 | K18: 6 | N18: =IF(OR(H18="",I18="",J18="",K18=""),"",(IF(H18>I18,1,0)+IF(J18>K18,1,0)+IF(AND(L18<>"",M18<>""),IF(L18>M18,1,0),0))) -> 0 | O18: =IF(N18="","",(IF(H18<I18,1,0)+IF(J18<K18,1,0)+IF(AND(L18<>"",M18<>""),IF(L18<M18,1,0),0))) -> 2 | P18: =IF(N18="","",IF(N18>O18,"A","B")) -> B | Q18: =IF(N18="","",H18+J18+IF(L18="",0,L18)) -> 8 | R18: =IF(N18="","",I18+K18+IF(M18="",0,M18)) -> 12 | S18: =IF(N18="","",Q18-R18) -> -4 | T18: =IF(OR(C18<>$X$2,P18=""),"",MIN(MAX(0,S18)*$X$5,$X$6)) -> 0 | U18: =IF(OR(C18<>$X$2,P18=""),"",MIN(MAX(0,-S18)*$X$5,$X$6)) -> 0.08 | V18: =IF($Z$2="","",OR($D18=$Z$2,$E18=$Z$2,$F18=$Z$2,$G18=$Z$2)) -> FALSE | AA18: =IF($B18="","",YEAR($B18)) -> 2025 | AB18: =IF($Z$5="Todas",TRUE,$AA18=$Z$5) -> TRUE
A19: 18 | B19: 45806 | C19: Liga | D19: Imobach González | E19: Israel Suárez | F19: Alberto Nunes | G19: Carmelo Rosario | H19: 7 | I19: 5 | J19: 6 | K19: 1 | N19: =IF(OR(H19="",I19="",J19="",K19=""),"",(IF(H19>I19,1,0)+IF(J19>K19,1,0)+IF(AND(L19<>"",M19<>""),IF(L19>M19,1,0),0))) -> 2 | O19: =IF(N19="","",(IF(H19<I19,1,0)+IF(J19<K19,1,0)+IF(AND(L19<>"",M19<>""),IF(L19<M19,1,0),0))) -> 0 | P19: =IF(N19="","",IF(N19>O19,"A","B")) -> A | Q19: =IF(N19="","",H19+J19+IF(L19="",0,L19)) -> 13 | R19: =IF(N19="","",I19+K19+IF(M19="",0,M19)) -> 6 | S19: =IF(N19="","",Q19-R19) -> 7 | T19: =IF(OR(C19<>$X$2,P19=""),"",MIN(MAX(0,S19)*$X$5,$X$6)) -> 0.14 | U19: =IF(OR(C19<>$X$2,P19=""),"",MIN(MAX(0,-S19)*$X$5,$X$6)) -> 0 | V19: =IF($Z$2="","",OR($D19=$Z$2,$E19=$Z$2,$F19=$Z$2,$G19=$Z$2)) -> FALSE | AA19: =IF($B19="","",YEAR($B19)) -> 2025 | AB19: =IF($Z$5="Todas",TRUE,$AA19=$Z$5) -> TRUE
A20: 19 | B20: 45806 | C20: Liga | D20: Yeray Armas | E20: Cristo Marrero | F20: César Morales | G20: Javier suarez | H20: 1 | I20: 6 | J20: 4 | K20: 6 | N20: =IF(OR(H20="",I20="",J20="",K20=""),"",(IF(H20>I20,1,0)+IF(J20>K20,1,0)+IF(AND(L20<>"",M20<>""),IF(L20>M20,1,0),0))) -> 0 | O20: =IF(N20="","",(IF(H20<I20,1,0)+IF(J20<K20,1,0)+IF(AND(L20<>"",M20<>""),IF(L20<M20,1,0),0))) -> 2 | P20: =IF(N20="","",IF(N20>O20,"A","B")) -> B | Q20: =IF(N20="","",H20+J20+IF(L20="",0,L20)) -> 5 | R20: =IF(N20="","",I20+K20+IF(M20="",0,M20)) -> 12 | S20: =IF(N20="","",Q20-R20) -> -7 | T20: =IF(OR(C20<>$X$2,P20=""),"",MIN(MAX(0,S20)*$X$5,$X$6)) -> 0 | U20: =IF(OR(C20<>$X$2,P20=""),"",MIN(MAX(0,-S20)*$X$5,$X$6)) -> 0.14 | V20: =IF($Z$2="","",OR($D20=$Z$2,$E20=$Z$2,$F20=$Z$2,$G20=$Z$2)) -> TRUE | AA20: =IF($B20="","",YEAR($B20)) -> 2025 | AB20: =IF($Z$5="Todas",TRUE,$AA20=$Z$5) -> TRUE
A21: 20 | B21: 45811 | C21: Liga | D21: Imobach González | E21: Javier suarez | F21: Cristo Marrero | G21: Javier Bonilla | H21: 6 | I21: 4 | J21: 6 | K21: 2 | N21: =IF(OR(H21="",I21="",J21="",K21=""),"",(IF(H21>I21,1,0)+IF(J21>K21,1,0)+IF(AND(L21<>"",M21<>""),IF(L21>M21,1,0),0))) -> 2 | O21: =IF(N21="","",(IF(H21<I21,1,0)+IF(J21<K21,1,0)+IF(AND(L21<>"",M21<>""),IF(L21<M21,1,0),0))) -> 0 | P21: =IF(N21="","",IF(N21>O21,"A","B")) -> A | Q21: =IF(N21="","",H21+J21+IF(L21="",0,L21)) -> 12 | R21: =IF(N21="","",I21+K21+IF(M21="",0,M21)) -> 6 | S21: =IF(N21="","",Q21-R21) -> 6 | T21: =IF(OR(C21<>$X$2,P21=""),"",MIN(MAX(0,S21)*$X$5,$X$6)) -> 0.12 | U21: =IF(OR(C21<>$X$2,P21=""),"",MIN(MAX(0,-S21)*$X$5,$X$6)) -> 0 | V21: =IF($Z$2="","",OR($D21=$Z$2,$E21=$Z$2,$F21=$Z$2,$G21=$Z$2)) -> FALSE | AA21: =IF($B21="","",YEAR($B21)) -> 2025 | AB21: =IF($Z$5="Todas",TRUE,$AA21=$Z$5) -> TRUE
A22: 21 | B22: 45811 | C22: Liga | D22: Eva Pulido | E22: Nacho Navidad | F22: Guillermo Medina | G22: Wilfredo Santana | H22: 2 | I22: 6 | J22: 3 | K22: 6 | N22: =IF(OR(H22="",I22="",J22="",K22=""),"",(IF(H22>I22,1,0)+IF(J22>K22,1,0)+IF(AND(L22<>"",M22<>""),IF(L22>M22,1,0),0))) -> 0 | O22: =IF(N22="","",(IF(H22<I22,1,0)+IF(J22<K22,1,0)+IF(AND(L22<>"",M22<>""),IF(L22<M22,1,0),0))) -> 2 | P22: =IF(N22="","",IF(N22>O22,"A","B")) -> B | Q22: =IF(N22="","",H22+J22+IF(L22="",0,L22)) -> 5 | R22: =IF(N22="","",I22+K22+IF(M22="",0,M22)) -> 12 | S22: =IF(N22="","",Q22-R22) -> -7 | T22: =IF(OR(C22<>$X$2,P22=""),"",MIN(MAX(0,S22)*$X$5,$X$6)) -> 0 | U22: =IF(OR(C22<>$X$2,P22=""),"",MIN(MAX(0,-S22)*$X$5,$X$6)) -> 0.14 | V22: =IF($Z$2="","",OR($D22=$Z$2,$E22=$Z$2,$F22=$Z$2,$G22=$Z$2)) -> FALSE | AA22: =IF($B22="","",YEAR($B22)) -> 2025 | AB22: =IF($Z$5="Todas",TRUE,$AA22=$Z$5) -> TRUE
A23: 22 | B23: 45814 | C23: Liga | D23: Yeray Armas | E23: Carmelo Rosario | F23: Nacho Navidad | G23: Eva Pulido | H23: 6 | I23: 3 | J23: 6 | K23: 3 | N23: =IF(OR(H23="",I23="",J23="",K23=""),"",(IF(H23>I23,1,0)+IF(J23>K23,1,0)+IF(AND(L23<>"",M23<>""),IF(L23>M23,1,0),0))) -> 2 | O23: =IF(N23="","",(IF(H23<I23,1,0)+IF(J23<K23,1,0)+IF(AND(L23<>"",M23<>""),IF(L23<M23,1,0),0))) -> 0 | P23: =IF(N23="","",IF(N23>O23,"A","B")) -> A | Q23: =IF(N23="","",H23+J23+IF(L23="",0,L23)) -> 12 | R23: =IF(N23="","",I23+K23+IF(M23="",0,M23)) -> 6 | S23: =IF(N23="","",Q23-R23) -> 6 | T23: =IF(OR(C23<>$X$2,P23=""),"",MIN(MAX(0,S23)*$X$5,$X$6)) -> 0.12 | U23: =IF(OR(C23<>$X$2,P23=""),"",MIN(MAX(0,-S23)*$X$5,$X$6)) -> 0 | V23: =IF($Z$2="","",OR($D23=$Z$2,$E23=$Z$2,$F23=$Z$2,$G23=$Z$2)) -> TRUE | AA23: =IF($B23="","",YEAR($B23)) -> 2025 | AB23: =IF($Z$5="Todas",TRUE,$AA23=$Z$5) -> TRUE
A24: 23 | B24: 45814 | C24: Liga | D24: Imobach González | E24: Nacho Navidad | F24: Guillermo Medina | G24: Javier Bonilla | H24: 6 | I24: 1 | J24: 6 | K24: 3 | N24: =IF(OR(H24="",I24="",J24="",K24=""),"",(IF(H24>I24,1,0)+IF(J24>K24,1,0)+IF(AND(L24<>"",M24<>""),IF(L24>M24,1,0),0))) -> 2 | O24: =IF(N24="","",(IF(H24<I24,1,0)+IF(J24<K24,1,0)+IF(AND(L24<>"",M24<>""),IF(L24<M24,1,0),0))) -> 0 | P24: =IF(N24="","",IF(N24>O24,"A","B")) -> A | Q24: =IF(N24="","",H24+J24+IF(L24="",0,L24)) -> 12 | R24: =IF(N24="","",I24+K24+IF(M24="",0,M24)) -> 4 | S24: =IF(N24="","",Q24-R24) -> 8 | T24: =IF(OR(C24<>$X$2,P24=""),"",MIN(MAX(0,S24)*$X$5,$X$6)) -> 0.16 | U24: =IF(OR(C24<>$X$2,P24=""),"",MIN(MAX(0,-S24)*$X$5,$X$6)) -> 0 | V24: =IF($Z$2="","",OR($D24=$Z$2,$E24=$Z$2,$F24=$Z$2,$G24=$Z$2)) -> FALSE | AA24: =IF($B24="","",YEAR($B24)) -> 2025 | AB24: =IF($Z$5="Todas",TRUE,$AA24=$Z$5) -> TRUE
A25: 24 | B25: 45819 | C25: Liga | D25: Carmelo Rosario | E25: Javier Bonilla | F25: Imobach González | G25: Nacho Navidad | H25: 6 | I25: 2 | J25: 4 | K25: 6 | L25: 6 | M25: 2 | N25: =IF(OR(H25="",I25="",J25="",K25=""),"",(IF(H25>I25,1,0)+IF(J25>K25,1,0)+IF(AND(L25<>"",M25<>""),IF(L25>M25,1,0),0))) -> 2 | O25: =IF(N25="","",(IF(H25<I25,1,0)+IF(J25<K25,1,0)+IF(AND(L25<>"",M25<>""),IF(L25<M25,1,0),0))) -> 1 | P25: =IF(N25="","",IF(N25>O25,"A","B")) -> A | Q25: =IF(N25="","",H25+J25+IF(L25="",0,L25)) -> 16 | R25: =IF(N25="","",I25+K25+IF(M25="",0,M25)) -> 10 | S25: =IF(N25="","",Q25-R25) -> 6 | T25: =IF(OR(C25<>$X$2,P25=""),"",MIN(MAX(0,S25)*$X$5,$X$6)) -> 0.12 | U25: =IF(OR(C25<>$X$2,P25=""),"",MIN(MAX(0,-S25)*$X$5,$X$6)) -> 0 | V25: =IF($Z$2="","",OR($D25=$Z$2,$E25=$Z$2,$F25=$Z$2,$G25=$Z$2)) -> FALSE | AA25: =IF($B25="","",YEAR($B25)) -> 2025 | AB25: =IF($Z$5="Todas",TRUE,$AA25=$Z$5) -> TRUE
A26: 25 | B26: 45821 | C26: Liga | D26: Imobach González | E26: Javier Bonilla | F26: José López | G26: Nacho Navidad | H26: 3 | I26: 6 | J26: 2 | K26: 6 | N26: =IF(OR(H26="",I26="",J26="",K26=""),"",(IF(H26>I26,1,0)+IF(J26>K26,1,0)+IF(AND(L26<>"",M26<>""),IF(L26>M26,1,0),0))) -> 0 | O26: =IF(N26="","",(IF(H26<I26,1,0)+IF(J26<K26,1,0)+IF(AND(L26<>"",M26<>""),IF(L26<M26,1,0),0))) -> 2 | P26: =IF(N26="","",IF(N26>O26,"A","B")) -> B | Q26: =IF(N26="","",H26+J26+IF(L26="",0,L26)) -> 5 | R26: =IF(N26="","",I26+K26+IF(M26="",0,M26)) -> 12 | S26: =IF(N26="","",Q26-R26) -> -7 | T26: =IF(OR(C26<>$X$2,P26=""),"",MIN(MAX(0,S26)*$X$5,$X$6)) -> 0 | U26: =IF(OR(C26<>$X$2,P26=""),"",MIN(MAX(0,-S26)*$X$5,$X$6)) -> 0.14 | V26: =IF($Z$2="","",OR($D26=$Z$2,$E26=$Z$2,$F26=$Z$2,$G26=$Z$2)) -> FALSE | AA26: =IF($B26="","",YEAR($B26)) -> 2025 | AB26: =IF($Z$5="Todas",TRUE,$AA26=$Z$5) -> TRUE
A27: 26 | B27: 45828 | C27: Liga | D27: Eva Pulido | E27: Carmelo Rosario | F27: Guillermo Medina | G27: Nacho Navidad | H27: 6 | I27: 3 | J27: 1 | K27: 6 | L27: 6 | M27: 3 | N27: =IF(OR(H27="",I27="",J27="",K27=""),"",(IF(H27>I27,1,0)+IF(J27>K27,1,0)+IF(AND(L27<>"",M27<>""),IF(L27>M27,1,0),0))) -> 2 | O27: =IF(N27="","",(IF(H27<I27,1,0)+IF(J27<K27,1,0)+IF(AND(L27<>"",M27<>""),IF(L27<M27,1,0),0))) -> 1 | P27: =IF(N27="","",IF(N27>O27,"A","B")) -> A | Q27: =IF(N27="","",H27+J27+IF(L27="",0,L27)) -> 13 | R27: =IF(N27="","",I27+K27+IF(M27="",0,M27)) -> 12 | S27: =IF(N27="","",Q27-R27) -> 1 | T27: =IF(OR(C27<>$X$2,P27=""),"",MIN(MAX(0,S27)*$X$5,$X$6)) -> 0.02 | U27: =IF(OR(C27<>$X$2,P27=""),"",MIN(MAX(0,-S27)*$X$5,$X$6)) -> 0 | V27: =IF($Z$2="","",OR($D27=$Z$2,$E27=$Z$2,$F27=$Z$2,$G27=$Z$2)) -> FALSE | AA27: =IF($B27="","",YEAR($B27)) -> 2025 | AB27: =IF($Z$5="Todas",TRUE,$AA27=$Z$5) -> TRUE
A28: 27 | B28: 45839 | C28: Liga | D28: Yeray Armas | E28: Javier Bonilla | F28: Carmelo Rosario | G28: César Morales | H28: 3 | I28: 6 | J28: 2 | K28: 6 | N28: =IF(OR(H28="",I28="",J28="",K28=""),"",(IF(H28>I28,1,0)+IF(J28>K28,1,0)+IF(AND(L28<>"",M28<>""),IF(L28>M28,1,0),0))) -> 0 | O28: =IF(N28="","",(IF(H28<I28,1,0)+IF(J28<K28,1,0)+IF(AND(L28<>"",M28<>""),IF(L28<M28,1,0),0))) -> 2 | P28: =IF(N28="","",IF(N28>O28,"A","B")) -> B | Q28: =IF(N28="","",H28+J28+IF(L28="",0,L28)) -> 5 | R28: =IF(N28="","",I28+K28+IF(M28="",0,M28)) -> 12 | S28: =IF(N28="","",Q28-R28) -> -7 | T28: =IF(OR(C28<>$X$2,P28=""),"",MIN(MAX(0,S28)*$X$5,$X$6)) -> 0 | U28: =IF(OR(C28<>$X$2,P28=""),"",MIN(MAX(0,-S28)*$X$5,$X$6)) -> 0.14 | V28: =IF($Z$2="","",OR($D28=$Z$2,$E28=$Z$2,$F28=$Z$2,$G28=$Z$2)) -> TRUE | AA28: =IF($B28="","",YEAR($B28)) -> 2025 | AB28: =IF($Z$5="Todas",TRUE,$AA28=$Z$5) -> TRUE
A29: 28 | B29: 45840 | C29: Liga | D29: César Morales | E29: Alberto Nunes | F29: Israel Suárez | G29: Nacho Navidad | H29: 2 | I29: 6 | J29: 5 | K29: 7 | N29: =IF(OR(H29="",I29="",J29="",K29=""),"",(IF(H29>I29,1,0)+IF(J29>K29,1,0)+IF(AND(L29<>"",M29<>""),IF(L29>M29,1,0),0))) -> 0 | O29: =IF(N29="","",(IF(H29<I29,1,0)+IF(J29<K29,1,0)+IF(AND(L29<>"",M29<>""),IF(L29<M29,1,0),0))) -> 2 | P29: =IF(N29="","",IF(N29>O29,"A","B")) -> B | Q29: =IF(N29="","",H29+J29+IF(L29="",0,L29)) -> 7 | R29: =IF(N29="","",I29+K29+IF(M29="",0,M29)) -> 13 | S29: =IF(N29="","",Q29-R29) -> -6 | T29: =IF(OR(C29<>$X$2,P29=""),"",MIN(MAX(0,S29)*$X$5,$X$6)) -> 0 | U29: =IF(OR(C29<>$X$2,P29=""),"",MIN(MAX(0,-S29)*$X$5,$X$6)) -> 0.12 | V29: =IF($Z$2="","",OR($D29=$Z$2,$E29=$Z$2,$F29=$Z$2,$G29=$Z$2)) -> FALSE | AA29: =IF($B29="","",YEAR($B29)) -> 2025 | AB29: =IF($Z$5="Todas",TRUE,$AA29=$Z$5) -> TRUE
A30: 29 | B30: 45841 | C30: Liga | D30: Israel Suárez | E30: Yeray Armas | F30: Javier suarez | G30: Guillermo Medina | H30: 0 | I30: 6 | J30: 0 | K30: 6 | N30: =IF(OR(H30="",I30="",J30="",K30=""),"",(IF(H30>I30,1,0)+IF(J30>K30,1,0)+IF(AND(L30<>"",M30<>""),IF(L30>M30,1,0),0))) -> 0 | O30: =IF(N30="","",(IF(H30<I30,1,0)+IF(J30<K30,1,0)+IF(AND(L30<>"",M30<>""),IF(L30<M30,1,0),0))) -> 2 | P30: =IF(N30="","",IF(N30>O30,"A","B")) -> B | Q30: =IF(N30="","",H30+J30+IF(L30="",0,L30)) -> 0 | R30: =IF(N30="","",I30+K30+IF(M30="",0,M30)) -> 12 | S30: =IF(N30="","",Q30-R30) -> -12 | T30: =IF(OR(C30<>$X$2,P30=""),"",MIN(MAX(0,S30)*$X$5,$X$6)) -> 0 | U30: =IF(OR(C30<>$X$2,P30=""),"",MIN(MAX(0,-S30)*$X$5,$X$6)) -> 0.24 | V30: =IF($Z$2="","",OR($D30=$Z$2,$E30=$Z$2,$F30=$Z$2,$G30=$Z$2)) -> TRUE | AA30: =IF($B30="","",YEAR($B30)) -> 2025 | AB30: =IF($Z$5="Todas",TRUE,$AA30=$Z$5) -> TRUE
A31: 30 | B31: 45841 | C31: Liga | D31: Israel Suárez | E31: Guillermo Medina | F31: Yeray Armas | G31: Javier suarez | H31: 5 | I31: 7 | J31: 6 | K31: 2 | L31: 6 | M31: 4 | N31: =IF(OR(H31="",I31="",J31="",K31=""),"",(IF(H31>I31,1,0)+IF(J31>K31,1,0)+IF(AND(L31<>"",M31<>""),IF(L31>M31,1,0),0))) -> 2 | O31: =IF(N31="","",(IF(H31<I31,1,0)+IF(J31<K31,1,0)+IF(AND(L31<>"",M31<>""),IF(L31<M31,1,0),0))) -> 1 | P31: =IF(N31="","",IF(N31>O31,"A","B")) -> A | Q31: =IF(N31="","",H31+J31+IF(L31="",0,L31)) -> 17 | R31: =IF(N31="","",I31+K31+IF(M31="",0,M31)) -> 13 | S31: =IF(N31="","",Q31-R31) -> 4 | T31: =IF(OR(C31<>$X$2,P31=""),"",MIN(MAX(0,S31)*$X$5,$X$6)) -> 0.08 | U31: =IF(OR(C31<>$X$2,P31=""),"",MIN(MAX(0,-S31)*$X$5,$X$6)) -> 0 | V31: =IF($Z$2="","",OR($D31=$Z$2,$E31=$Z$2,$F31=$Z$2,$G31=$Z$2)) -> TRUE | AA31: =IF($B31="","",YEAR($B31)) -> 2025 | AB31: =IF($Z$5="Todas",TRUE,$AA31=$Z$5) -> TRUE
A32: 31 | B32: 45842 | C32: Liga | D32: Imobach González | E32: Yeray Armas | F32: Guillermo Medina | G32: Israel Suárez | H32: 3 | I32: 6 | J32: 6 | K32: 4 | L32: 5 | M32: 7 | N32: =IF(OR(H32="",I32="",J32="",K32=""),"",(IF(H32>I32,1,0)+IF(J32>K32,1,0)+IF(AND(L32<>"",M32<>""),IF(L32>M32,1,0),0))) -> 1 | O32: =IF(N32="","",(IF(H32<I32,1,0)+IF(J32<K32,1,0)+IF(AND(L32<>"",M32<>""),IF(L32<M32,1,0),0))) -> 2 | P32: =IF(N32="","",IF(N32>O32,"A","B")) -> B | Q32: =IF(N32="","",H32+J32+IF(L32="",0,L32)) -> 14 | R32: =IF(N32="","",I32+K32+IF(M32="",0,M32)) -> 17 | S32: =IF(N32="","",Q32-R32) -> -3 | T32: =IF(OR(C32<>$X$2,P32=""),"",MIN(MAX(0,S32)*$X$5,$X$6)) -> 0 | U32: =IF(OR(C32<>$X$2,P32=""),"",MIN(MAX(0,-S32)*$X$5,$X$6)) -> 0.06 | V32: =IF($Z$2="","",OR($D32=$Z$2,$E32=$Z$2,$F32=$Z$2,$G32=$Z$2)) -> TRUE | AA32: =IF($B32="","",YEAR($B32)) -> 2025 | AB32: =IF($Z$5="Todas",TRUE,$AA32=$Z$5) -> TRUE
A33: 32 | B33: 45847 | C33: Liga | D33: Israel Suárez | E33: Carmelo Rosario | F33: Guillermo Medina | G33: Alberto Nunes | H33: 6 | I33: 2 | J33: 4 | K33: 6 | L33: 6 | M33: 2 | N33: =IF(OR(H33="",I33="",J33="",K33=""),"",(IF(H33>I33,1,0)+IF(J33>K33,1,0)+IF(AND(L33<>"",M33<>""),IF(L33>M33,1,0),0))) -> 2 | O33: =IF(N33="","",(IF(H33<I33,1,0)+IF(J33<K33,1,0)+IF(AND(L33<>"",M33<>""),IF(L33<M33,1,0),0))) -> 1 | P33: =IF(N33="","",IF(N33>O33,"A","B")) -> A | Q33: =IF(N33="","",H33+J33+IF(L33="",0,L33)) -> 16 | R33: =IF(N33="","",I33+K33+IF(M33="",0,M33)) -> 10 | S33: =IF(N33="","",Q33-R33) -> 6 | T33: =IF(OR(C33<>$X$2,P33=""),"",MIN(MAX(0,S33)*$X$5,$X$6)) -> 0.12 | U33: =IF(OR(C33<>$X$2,P33=""),"",MIN(MAX(0,-S33)*$X$5,$X$6)) -> 0 | V33: =IF($Z$2="","",OR($D33=$Z$2,$E33=$Z$2,$F33=$Z$2,$G33=$Z$2)) -> FALSE | AA33: =IF($B33="","",YEAR($B33)) -> 2025 | AB33: =IF($Z$5="Todas",TRUE,$AA33=$Z$5) -> TRUE
A34: 33 | B34: 45848 | C34: Liga | D34: Yeray Armas | E34: Javier Bonilla | F34: Carmelo Rosario | G34: José Fernando | H34: 6 | I34: 4 | J34: 4 | K34: 6 | L34: 2 | M34: 6 | N34: =IF(OR(H34="",I34="",J34="",K34=""),"",(IF(H34>I34,1,0)+IF(J34>K34,1,0)+IF(AND(L34<>"",M34<>""),IF(L34>M34,1,0),0))) -> 1 | O34: =IF(N34="","",(IF(H34<I34,1,0)+IF(J34<K34,1,0)+IF(AND(L34<>"",M34<>""),IF(L34<M34,1,0),0))) -> 2 | P34: =IF(N34="","",IF(N34>O34,"A","B")) -> B | Q34: =IF(N34="","",H34+J34+IF(L34="",0,L34)) -> 12 | R34: =IF(N34="","",I34+K34+IF(M34="",0,M34)) -> 16 | S34: =IF(N34="","",Q34-R34) -> -4 | T34: =IF(OR(C34<>$X$2,P34=""),"",MIN(MAX(0,S34)*$X$5,$X$6)) -> 0 | U34: =IF(OR(C34<>$X$2,P34=""),"",MIN(MAX(0,-S34)*$X$5,$X$6)) -> 0.08 | V34: =IF($Z$2="","",OR($D34=$Z$2,$E34=$Z$2,$F34=$Z$2,$G34=$Z$2)) -> TRUE | AA34: =IF($B34="","",YEAR($B34)) -> 2025 | AB34: =IF($Z$5="Todas",TRUE,$AA34=$Z$5) -> TRUE
A35: 34 | B35: 45849 | C35: Liga | D35: Imobach González | E35: Javier suarez | F35: Carmelo Rosario | G35: Eva Pulido | H35: 6 | I35: 1 | J35: 6 | K35: 1 | N35: =IF(OR(H35="",I35="",J35="",K35=""),"",(IF(H35>I35,1,0)+IF(J35>K35,1,0)+IF(AND(L35<>"",M35<>""),IF(L35>M35,1,0),0))) -> 2 | O35: =IF(N35="","",(IF(H35<I35,1,0)+IF(J35<K35,1,0)+IF(AND(L35<>"",M35<>""),IF(L35<M35,1,0),0))) -> 0 | P35: =IF(N35="","",IF(N35>O35,"A","B")) -> A | Q35: =IF(N35="","",H35+J35+IF(L35="",0,L35)) -> 12 | R35: =IF(N35="","",I35+K35+IF(M35="",0,M35)) -> 2 | S35: =IF(N35="","",Q35-R35) -> 10 | T35: =IF(OR(C35<>$X$2,P35=""),"",MIN(MAX(0,S35)*$X$5,$X$6)) -> 0.2 | U35: =IF(OR(C35<>$X$2,P35=""),"",MIN(MAX(0,-S35)*$X$5,$X$6)) -> 0 | V35: =IF($Z$2="","",OR($D35=$Z$2,$E35=$Z$2,$F35=$Z$2,$G35=$Z$2)) -> FALSE | AA35: =IF($B35="","",YEAR($B35)) -> 2025 | AB35: =IF($Z$5="Todas",TRUE,$AA35=$Z$5) -> TRUE
A36: 35 | B36: 45852 | C36: Liga | D36: Alberto Nunes | E36: Cristo Marrero | F36: Carmelo Rosario | G36: Javier Bonilla | H36: 5 | I36: 7 | J36: 6 | K36: 4 | L36: 4 | M36: 6 | N36: =IF(OR(H36="",I36="",J36="",K36=""),"",(IF(H36>I36,1,0)+IF(J36>K36,1,0)+IF(AND(L36<>"",M36<>""),IF(L36>M36,1,0),0))) -> 1 | O36: =IF(N36="","",(IF(H36<I36,1,0)+IF(J36<K36,1,0)+IF(AND(L36<>"",M36<>""),IF(L36<M36,1,0),0))) -> 2 | P36: =IF(N36="","",IF(N36>O36,"A","B")) -> B | Q36: =IF(N36="","",H36+J36+IF(L36="",0,L36)) -> 15 | R36: =IF(N36="","",I36+K36+IF(M36="",0,M36)) -> 17 | S36: =IF(N36="","",Q36-R36) -> -2 | T36: =IF(OR(C36<>$X$2,P36=""),"",MIN(MAX(0,S36)*$X$5,$X$6)) -> 0 | U36: =IF(OR(C36<>$X$2,P36=""),"",MIN(MAX(0,-S36)*$X$5,$X$6)) -> 0.04 | V36: =IF($Z$2="","",OR($D36=$Z$2,$E36=$Z$2,$F36=$Z$2,$G36=$Z$2)) -> FALSE | AA36: =IF($B36="","",YEAR($B36)) -> 2025 | AB36: =IF($Z$5="Todas",TRUE,$AA36=$Z$5) -> TRUE
A37: 36 | B37: 45854 | C37: Liga | D37: Cristo Marrero | E37: Nacho Navidad | F37: Guillermo Medina | G37: Eva Pulido | H37: 6 | I37: 0 | J37: 6 | K37: 4 | N37: =IF(OR(H37="",I37="",J37="",K37=""),"",(IF(H37>I37,1,0)+IF(J37>K37,1,0)+IF(AND(L37<>"",M37<>""),IF(L37>M37,1,0),0))) -> 2 | O37: =IF(N37="","",(IF(H37<I37,1,0)+IF(J37<K37,1,0)+IF(AND(L37<>"",M37<>""),IF(L37<M37,1,0),0))) -> 0 | P37: =IF(N37="","",IF(N37>O37,"A","B")) -> A | Q37: =IF(N37="","",H37+J37+IF(L37="",0,L37)) -> 12 | R37: =IF(N37="","",I37+K37+IF(M37="",0,M37)) -> 4 | S37: =IF(N37="","",Q37-R37) -> 8 | T37: =IF(OR(C37<>$X$2,P37=""),"",MIN(MAX(0,S37)*$X$5,$X$6)) -> 0.16 | U37: =IF(OR(C37<>$X$2,P37=""),"",MIN(MAX(0,-S37)*$X$5,$X$6)) -> 0 | V37: =IF($Z$2="","",OR($D37=$Z$2,$E37=$Z$2,$F37=$Z$2,$G37=$Z$2)) -> FALSE | AA37: =IF($B37="","",YEAR($B37)) -> 2025 | AB37: =IF($Z$5="Todas",TRUE,$AA37=$Z$5) -> TRUE
A38: 37 | B38: 45854 | C38: Liga | D38: Cristo Marrero | E38: Eva Pulido | F38: Guillermo Medina | G38: Nacho Navidad | H38: 6 | I38: 4 | J38: 6 | K38: 0 | N38: =IF(OR(H38="",I38="",J38="",K38=""),"",(IF(H38>I38,1,0)+IF(J38>K38,1,0)+IF(AND(L38<>"",M38<>""),IF(L38>M38,1,0),0))) -> 2 | O38: =IF(N38="","",(IF(H38<I38,1,0)+IF(J38<K38,1,0)+IF(AND(L38<>"",M38<>""),IF(L38<M38,1,0),0))) -> 0 | P38: =IF(N38="","",IF(N38>O38,"A","B")) -> A | Q38: =IF(N38="","",H38+J38+IF(L38="",0,L38)) -> 12 | R38: =IF(N38="","",I38+K38+IF(M38="",0,M38)) -> 4 | S38: =IF(N38="","",Q38-R38) -> 8 | T38: =IF(OR(C38<>$X$2,P38=""),"",MIN(MAX(0,S38)*$X$5,$X$6)) -> 0.16 | U38: =IF(OR(C38<>$X$2,P38=""),"",MIN(MAX(0,-S38)*$X$5,$X$6)) -> 0 | V38: =IF($Z$2="","",OR($D38=$Z$2,$E38=$Z$2,$F38=$Z$2,$G38=$Z$2)) -> FALSE | AA38: =IF($B38="","",YEAR($B38)) -> 2025 | AB38: =IF($Z$5="Todas",TRUE,$AA38=$Z$5) -> TRUE
A39: 38 | B39: 45854 | C39: Liga | D39: Javier Bonilla | E39: Yeray Armas | F39: Javier suarez | G39: Carmelo Rosario | H39: 2 | I39: 6 | J39: 1 | K39: 6 | N39: =IF(OR(H39="",I39="",J39="",K39=""),"",(IF(H39>I39,1,0)+IF(J39>K39,1,0)+IF(AND(L39<>"",M39<>""),IF(L39>M39,1,0),0))) -> 0 | O39: =IF(N39="","",(IF(H39<I39,1,0)+IF(J39<K39,1,0)+IF(AND(L39<>"",M39<>""),IF(L39<M39,1,0),0))) -> 2 | P39: =IF(N39="","",IF(N39>O39,"A","B")) -> B | Q39: =IF(N39="","",H39+J39+IF(L39="",0,L39)) -> 3 | R39: =IF(N39="","",I39+K39+IF(M39="",0,M39)) -> 12 | S39: =IF(N39="","",Q39-R39) -> -9 | T39: =IF(OR(C39<>$X$2,P39=""),"",MIN(MAX(0,S39)*$X$5,$X$6)) -> 0 | U39: =IF(OR(C39<>$X$2,P39=""),"",MIN(MAX(0,-S39)*$X$5,$X$6)) -> 0.18 | V39: =IF($Z$2="","",OR($D39=$Z$2,$E39=$Z$2,$F39=$Z$2,$G39=$Z$2)) -> TRUE | AA39: =IF($B39="","",YEAR($B39)) -> 2025 | AB39: =IF($Z$5="Todas",TRUE,$AA39=$Z$5) -> TRUE
A40: 39 | B40: 45855 | C40: Liga | D40: Cristo Marrero | E40: Eva Pulido | F40: Nacho Navidad | G40: José Fernando | H40: 6 | I40: 4 | J40: 6 | K40: 3 | N40: =IF(OR(H40="",I40="",J40="",K40=""),"",(IF(H40>I40,1,0)+IF(J40>K40,1,0)+IF(AND(L40<>"",M40<>""),IF(L40>M40,1,0),0))) -> 2 | O40: =IF(N40="","",(IF(H40<I40,1,0)+IF(J40<K40,1,0)+IF(AND(L40<>"",M40<>""),IF(L40<M40,1,0),0))) -> 0 | P40: =IF(N40="","",IF(N40>O40,"A","B")) -> A | Q40: =IF(N40="","",H40+J40+IF(L40="",0,L40)) -> 12 | R40: =IF(N40="","",I40+K40+IF(M40="",0,M40)) -> 7 | S40: =IF(N40="","",Q40-R40) -> 5 | T40: =IF(OR(C40<>$X$2,P40=""),"",MIN(MAX(0,S40)*$X$5,$X$6)) -> 0.1 | U40: =IF(OR(C40<>$X$2,P40=""),"",MIN(MAX(0,-S40)*$X$5,$X$6)) -> 0 | V40: =IF($Z$2="","",OR($D40=$Z$2,$E40=$Z$2,$F40=$Z$2,$G40=$Z$2)) -> FALSE | AA40: =IF($B40="","",YEAR($B40)) -> 2025 | AB40: =IF($Z$5="Todas",TRUE,$AA40=$Z$5) -> TRUE
...

Sheet Ranking
A1: Pos | B1: Jugador | C1: PJ | D1: V | E1: D | F1: GamesF | G1: GamesC | H1: Dif | I1: Bonus | J1: PuntosTotal | K1: SetsF | L1: SetsC | M1: Dif Sets
A2: =IF(B2="","",RANK(J2,$J$2:$J$61,0)+COUNTIFS($J$2:$J$61,J2,$H$2:$H$61,">"&H2)+COUNTIFS($J$2:$J$61,J2,$H$2:$H$61,H2,$M$2:$M$61,">"&M2)+COUNTIFS($J$2:$J$61,J2,$H$2:$H$61,H2,$M$2:$M$61,M2,$D$2:$D$61,">"&D2)+COUNTIFS($J$2:$J$61,J2,$H$2:$H$61,H2,$M$2:$M$61,M2,$D$2:$D$61,D2,$B$2:$B$61,">"&B2)) -> 1 | B2: =IF(Jugadores!B6="","",Jugadores!B6) -> Carmelo Rosario | C2: =IF(B2="","",COUNTIFS(Partidos!$C:$C,Partidos!$X$2,Partidos!$D:$D,B2)+COUNTIFS(Partidos!$C:$C,Partidos!$X$2,Partidos!$E:$E,B2)+COUNTIFS(Partidos!$C:$C,Partidos!$X$2,Partidos!$F:$F,B2)+COUNTIFS(Partidos!$C:$C,Partidos!$X$2,Partidos!$G:$G,B2)) -> 35 | D2: =IF(B2="","",COUNTIFS(Partidos!$C:$C,Partidos!$X$2,Partidos!$P:$P,"A",Partidos!$D:$D,B2)+COUNTIFS(Partidos!$C:$C,Partidos!$X$2,Partidos!$P:$P,"A",Partidos!$E:$E,B2)+COUNTIFS(Partidos!$C:$C,Partidos!$X$2,Partidos!$P:$P,"B",Partidos!$F:$F,B2)+COUNTIFS(Partidos!$C:$C,Partidos!$X$2,Partidos!$P:$P,"B",Partidos!$G:$G,B2)) -> 23 | E2: =IF(B2="","",C2-D2) -> 12 | F2: =IF(B2="","",SUMIFS(Partidos!$Q:$Q,Partidos!$C:$C,Partidos!$X$2,Partidos!$D:$D,B2)+SUMIFS(Partidos!$Q:$Q,Partidos!$C:$C,Partidos!$X$2,Partidos!$E:$E,B2)+SUMIFS(Partidos!$R:$R,Partidos!$C:$C,Partidos!$X$2,Partidos!$F:$F,B2)+SUMIFS(Partidos!$R:$R,Partidos!$C:$C,Partidos!$X$2,Partidos!$G:$G,B2)) -> 422 | G2: =IF(B2="","",SUMIFS(Partidos!$R:$R,Partidos!$C:$C,Partidos!$X$2,Partidos!$D:$D,B2)+SUMIFS(Partidos!$R:$R,Partidos!$C:$C,Partidos!$X$2,Partidos!$E:$E,B2)+SUMIFS(Partidos!$Q:$Q,Partidos!$C:$C,Partidos!$X$2,Partidos!$F:$F,B2)+SUMIFS(Partidos!$Q:$Q,Partidos!$C:$C,Partidos!$X$2,Partidos!$G:$G,B2)) -> 361 | H2: =IF(B2="","",F2-G2) -> 61 | I2: =IF(B2="","",SUMIFS(Partidos!$T:$T,Partidos!$C:$C,Partidos!$X$2,Partidos!$D:$D,B2)+SUMIFS(Partidos!$T:$T,Partidos!$C:$C,Partidos!$X$2,Partidos!$E:$E,B2)+SUMIFS(Partidos!$U:$U,Partidos!$C:$C,Partidos!$X$2,Partidos!$F:$F,B2)+SUMIFS(Partidos!$U:$U,Partidos!$C:$C,Partidos!$X$2,Partidos!$G:$G,B2)) -> 2.48 | J2: =IF(B2="","",D2*Partidos!$X$3 + E2*Partidos!$X$4 + I2) -> 48.48 | K2: =IF(B2="","",SUMIFS(Partidos!$N:$N,Partidos!$C:$C,Partidos!$X$2,Partidos!$D:$D,B2)+SUMIFS(Partidos!$N:$N,Partidos!$C:$C,Partidos!$X$2,Partidos!$E:$E,B2)+SUMIFS(Partidos!$O:$O,Partidos!$C:$C,Partidos!$X$2,Partidos!$F:$F,B2)+SUMIFS(Partidos!$O:$O,Partidos!$C:$C,Partidos!$X$2,Partidos!$G:$G,B2)) -> 50 | L2: =IF(B2="","",SUMIFS(Partidos!$O:$O,Partidos!$C:$C,Partidos!$X$2,Partidos!$D:$D,B2)+SUMIFS(Partidos!$O:$O,Partidos!$C:$C,Partidos!$X$2,Partidos!$E:$E,B2)+SUMIFS(Partidos!$N:$N,Partidos!$C:$C,Partidos!$X$2,Partidos!$F:$F,B2)+SUMIFS(Partidos!$N:$N,Partidos!$C:$C,Partidos!$X$2,Partidos!$G:$G,B2)) -> 34 | M2: =IF(B2="","",K2-L2) -> 16
A3: =IF(B3="","",RANK(J3,$J$2:$J$61,0)+COUNTIFS($J$2:$J$61,J3,$H$2:$H$61,">"&H3)+COUNTIFS($J$2:$J$61,J3,$H$2:$H$61,H3,$M$2:$M$61,">"&M3)+COUNTIFS($J$2:$J$61,J3,$H$2:$H$61,H3,$M$2:$M$61,M3,$D$2:$D$61,">"&D3)+COUNTIFS($J$2:$J$61,J3,$H$2:$H$61,H3,$M$2:$M$61,M3,$D$2:$D$61,D3,$B$2:$B$61,">"&B3)) -> 2 | B3: =IF(Jugadores!B2="","",Jugadores!B2) -> Javier suarez | C3: =IF(B3="","",COUNTIFS(Partidos!$C:$C,Partidos!$X$2,Partidos!$D:$D,B3)+COUNTIFS(Partidos!$C:$C,Partidos!$X$2,Partidos!$E:$E,B3)+COUNTIFS(Partidos!$C:$C,Partidos!$X$2,Partidos!$F:$F,B3)+COUNTIFS(Partidos!$C:$C,Partidos!$X$2,Partidos!$G:$G,B3)) -> 28 | D3: =IF(B3="","",COUNTIFS(Partidos!$C:$C,Partidos!$X$2,Partidos!$P:$P,"A",Partidos!$D:$D,B3)+COUNTIFS(Partidos!$C:$C,Partidos!$X$2,Partidos!$P:$P,"A",Partidos!$E:$E,B3)+COUNTIFS(Partidos!$C:$C,Partidos!$X$2,Partidos!$P:$P,"B",Partidos!$F:$F,B3)+COUNTIFS(Partidos!$C:$C,Partidos!$X$2,Partidos!$P:$P,"B",Partidos!$G:$G,B3)) -> 19 | E3: =IF(B3="","",C3-D3) -> 9 | F3: =IF(B3="","",SUMIFS(Partidos!$Q:$Q,Partidos!$C:$C,Partidos!$X$2,Partidos!$D:$D,B3)+SUMIFS(Partidos!$Q:$Q,Partidos!$C:$C,Partidos!$X$2,Partidos!$E:$E,B3)+SUMIFS(Partidos!$R:$R,Partidos!$C:$C,Partidos!$X$2,Partidos!$F:$F,B3)+SUMIFS(Partidos!$R:$R,Partidos!$C:$C,Partidos!$X$2,Partidos!$G:$G,B3)) -> 349 | G3: =IF(B3="","",SUMIFS(Partidos!$R:$R,Partidos!$C:$C,Partidos!$X$2,Partidos!$D:$D,B3)+SUMIFS(Partidos!$R:$R,Partidos!$C:$C,Partidos!$X$2,Partidos!$E:$E,B3)+SUMIFS(Partidos!$Q:$Q,Partidos!$C:$C,Partidos!$X$2,Partidos!$F:$F,B3)+SUMIFS(Partidos!$Q:$Q,Partidos!$C:$C,Partidos!$X$2,Partidos!$G:$G,B3)) -> 249 | H3: =IF(B3="","",F3-G3) -> 100 | I3: =IF(B3="","",SUMIFS(Partidos!$T:$T,Partidos!$C:$C,Partidos!$X$2,Partidos!$D:$D,B3)+SUMIFS(Partidos!$T:$T,Partidos!$C:$C,Partidos!$X$2,Partidos!$E:$E,B3)+SUMIFS(Partidos!$U:$U,Partidos!$C:$C,Partidos!$X$2,Partidos!$F:$F,B3)+SUMIFS(Partidos!$U:$U,Partidos!$C:$C,Partidos!$X$2,Partidos!$G:$G,B3)) -> 2.64 | J3: =IF(B3="","",D3*Partidos!$X$3 + E3*Partidos!$X$4 + I3) -> 40.64 | K3: =IF(B3="","",SUMIFS(Partidos!$N:$N,Partidos!$C:$C,Partidos!$X$2,Partidos!$D:$D,B3)+SUMIFS(Partidos!$N:$N,Partidos!$C:$C,Partidos!$X$2,Partidos!$E:$E,B3)+SUMIFS(Partidos!$O:$O,Partidos!$C:$C,Partidos!$X$2,Partidos!$F:$F,B3)+SUMIFS(Partidos!$O:$O,Partidos!$C:$C,Partidos!$X$2,Partidos!$G:$G,B3)) -> 45 | L3: =IF(B3="","",SUMIFS(Partidos!$O:$O,Partidos!$C:$C,Partidos!$X$2,Partidos!$D:$D,B3)+SUMIFS(Partidos!$O:$O,Partidos!$C:$C,Partidos!$X$2,Partidos!$E:$E,B3)+SUMIFS(Partidos!$N:$N,Partidos!$C:$C,Partidos!$X$2,Partidos!$F:$F,B3)+SUMIFS(Partidos!$N:$N,Partidos!$C:$C,Partidos!$X$2,Partidos!$G:$G,B3)) -> 20 | M3: =IF(B3="","",K3-L3) -> 25
A4: =IF(B4="","",RANK(J4,$J$2:$J$61,0)+COUNTIFS($J$2:$J$61,J4,$H$2:$H$61,">"&H4)+COUNTIFS($J$2:$J$61,J4,$H$2:$H$61,H4,$M$2:$M$61,">"&M4)+COUNTIFS($J$2:$J$61,J4,$H$2:$H$61,H4,$M$2:$M$61,M4,$D$2:$D$61,">"&D4)+COUNTIFS($J$2:$J$61,J4,$H$2:$H$61,H4,$M$2:$M$61,M4,$D$2:$D$61,D4,$B$2:$B$61,">"&B4)) -> 3 | B4: =IF(Jugadores!B11="","",Jugadores!B11) -> Javier Bonilla | C4: =IF(B4="","",COUNTIFS(Partidos!$C:$C,Partidos!$X$2,Partidos!$D:$D,B4)+COUNTIFS(Partidos!$C:$C,Partidos!$X$2,Partidos!$E:$E,B4)+COUNTIFS(Partidos!$C:$C,Partidos!$X$2,Partidos!$F:$F,B4)+COUNTIFS(Partidos!$C:$C,Partidos!$X$2,Partidos!$G:$G,B4)) -> 29 | D4: =IF(B4="","",COUNTIFS(Partidos!$C:$C,Partidos!$X$2,Partidos!$P:$P,"A",Partidos!$D:$D,B4)+COUNTIFS(Partidos!$C:$C,Partidos!$X$2,Partidos!$P:$P,"A",Partidos!$E:$E,B4)+COUNTIFS(Partidos!$C:$C,Partidos!$X$2,Partidos!$P:$P,"B",Partidos!$F:$F,B4)+COUNTIFS(Partidos!$C:$C,Partidos!$X$2,Partidos!$P:$P,"B",Partidos!$G:$G,B4)) -> 17 | E4: =IF(B4="","",C4-D4) -> 12 | F4: =IF(B4="","",SUMIFS(Partidos!$Q:$Q,Partidos!$C:$C,Partidos!$X$2,Partidos!$D:$D,B4)+SUMIFS(Partidos!$Q:$Q,Partidos!$C:$C,Partidos!$X$2,Partidos!$E:$E,B4)+SUMIFS(Partidos!$R:$R,Partidos!$C:$C,Partidos!$X$2,Partidos!$F:$F,B4)+SUMIFS(Partidos!$R:$R,Partidos!$C:$C,Partidos!$X$2,Partidos!$G:$G,B4)) -> 320 | G4: =IF(B4="","",SUMIFS(Partidos!$R:$R,Partidos!$C:$C,Partidos!$X$2,Partidos!$D:$D,B4)+SUMIFS(Partidos!$R:$R,Partidos!$C:$C,Partidos!$X$2,Partidos!$E:$E,B4)+SUMIFS(Partidos!$Q:$Q,Partidos!$C:$C,Partidos!$X$2,Partidos!$F:$F,B4)+SUMIFS(Partidos!$Q:$Q,Partidos!$C:$C,Partidos!$X$2,Partidos!$G:$G,B4)) -> 316 | H4: =IF(B4="","",F4-G4) -> 4 | I4: =IF(B4="","",SUMIFS(Partidos!$T:$T,Partidos!$C:$C,Partidos!$X$2,Partidos!$D:$D,B4)+SUMIFS(Partidos!$T:$T,Partidos!$C:$C,Partidos!$X$2,Partidos!$E:$E,B4)+SUMIFS(Partidos!$U:$U,Partidos!$C:$C,Partidos!$X$2,Partidos!$F:$F,B4)+SUMIFS(Partidos!$U:$U,Partidos!$C:$C,Partidos!$X$2,Partidos!$G:$G,B4)) -> 1.6 | J4: =IF(B4="","",D4*Partidos!$X$3 + E4*Partidos!$X$4 + I4) -> 35.6 | K4: =IF(B4="","",SUMIFS(Partidos!$N:$N,Partidos!$C:$C,Partidos!$X$2,Partidos!$D:$D,B4)+SUMIFS(Partidos!$N:$N,Partidos!$C:$C,Partidos!$X$2,Partidos!$E:$E,B4)+SUMIFS(Partidos!$O:$O,Partidos!$C:$C,Partidos!$X$2,Partidos!$F:$F,B4)+SUMIFS(Partidos!$O:$O,Partidos!$C:$C,Partidos!$X$2,Partidos!$G:$G,B4)) -> 37 | L4: =IF(B4="","",SUMIFS(Partidos!$O:$O,Partidos!$C:$C,Partidos!$X$2,Partidos!$D:$D,B4)+SUMIFS(Partidos!$O:$O,Partidos!$C:$C,Partidos!$X$2,Partidos!$E:$E,B4)+SUMIFS(Partidos!$N:$N,Partidos!$C:$C,Partidos!$X$2,Partidos!$F:$F,B4)+SUMIFS(Partidos!$N:$N,Partidos!$C:$C,Partidos!$X$2,Partidos!$G:$G,B4)) -> 30 | M4: =IF(B4="","",K4-L4) -> 7
A5: =IF(B5="","",RANK(J5,$J$2:$J$61,0)+COUNTIFS($J$2:$J$61,J5,$H$2:$H$61,">"&H5)+COUNTIFS($J$2:$J$61,J5,$H$2:$H$61,H5,$M$2:$M$61,">"&M5)+COUNTIFS($J$2:$J$61,J5,$H$2:$H$61,H5,$M$2:$M$61,M5,$D$2:$D$61,">"&D5)+COUNTIFS($J$2:$J$61,J5,$H$2:$H$61,H5,$M$2:$M$61,M5,$D$2:$D$61,D5,$B$2:$B$61,">"&B5)) -> 4 | B5: =IF(Jugadores!B7="","",Jugadores!B7) -> Israel Suárez | C5: =IF(B5="","",COUNTIFS(Partidos!$C:$C,Partidos!$X$2,Partidos!$D:$D,B5)+COUNTIFS(Partidos!$C:$C,Partidos!$X$2,Partidos!$E:$E,B5)+COUNTIFS(Partidos!$C:$C,Partidos!$X$2,Partidos!$F:$F,B5)+COUNTIFS(Partidos!$C:$C,Partidos!$X$2,Partidos!$G:$G,B5)) -> 20 | D5: =IF(B5="","",COUNTIFS(Partidos!$C:$C,Partidos!$X$2,Partidos!$P:$P,"A",Partidos!$D:$D,B5)+COUNTIFS(Partidos!$C:$C,Partidos!$X$2,Partidos!$P:$P,"A",Partidos!$E:$E,B5)+COUNTIFS(Partidos!$C:$C,Partidos!$X$2,Partidos!$P:$P,"B",Partidos!$F:$F,B5)+COUNTIFS(Partidos!$C:$C,Partidos!$X$2,Partidos!$P:$P,"B",Partidos!$G:$G,B5)) -> 15 | E5: =IF(B5="","",C5-D5) -> 5 | F5: =IF(B5="","",SUMIFS(Partidos!$Q:$Q,Partidos!$C:$C,Partidos!$X$2,Partidos!$D:$D,B5)+SUMIFS(Partidos!$Q:$Q,Partidos!$C:$C,Partidos!$X$2,Partidos!$E:$E,B5)+SUMIFS(Partidos!$R:$R,Partidos!$C:$C,Partidos!$X$2,Partidos!$F:$F,B5)+SUMIFS(Partidos!$R:$R,Partidos!$C:$C,Partidos!$X$2,Partidos!$G:$G,B5)) -> 247 | G5: =IF(B5="","",SUMIFS(Partidos!$R:$R,Partidos!$C:$C,Partidos!$X$2,Partidos!$D:$D,B5)+SUMIFS(Partidos!$R:$R,Partidos!$C:$C,Partidos!$X$2,Partidos!$E:$E,B5)+SUMIFS(Partidos!$Q:$Q,Partidos!$C:$C,Partidos!$X$2,Partidos!$F:$F,B5)+SUMIFS(Partidos!$Q:$Q,Partidos!$C:$C,Partidos!$X$2,Partidos!$G:$G,B5)) -> 211 | H5: =IF(B5="","",F5-G5) -> 36 | I5: =IF(B5="","",SUMIFS(Partidos!$T:$T,Partidos!$C:$C,Partidos!$X$2,Partidos!$D:$D,B5)+SUMIFS(Partidos!$T:$T,Partidos!$C:$C,Partidos!$X$2,Partidos!$E:$E,B5)+SUMIFS(Partidos!$U:$U,Partidos!$C:$C,Partidos!$X$2,Partidos!$F:$F,B5)+SUMIFS(Partidos!$U:$U,Partidos!$C:$C,Partidos!$X$2,Partidos!$G:$G,B5)) -> 1.34 | J5: =IF(B5="","",D5*Partidos!$X$3 + E5*Partidos!$X$4 + I5) -> 31.34 | K5: =IF(B5="","",SUMIFS(Partidos!$N:$N,Partidos!$C:$C,Partidos!$X$2,Partidos!$D:$D,B5)+SUMIFS(Partidos!$N:$N,Partidos!$C:$C,Partidos!$X$2,Partidos!$E:$E,B5)+SUMIFS(Partidos!$O:$O,Partidos!$C:$C,Partidos!$X$2,Partidos!$F:$F,B5)+SUMIFS(Partidos!$O:$O,Partidos!$C:$C,Partidos!$X$2,Partidos!$G:$G,B5)) -> 31 | L5: =IF(B5="","",SUMIFS(Partidos!$O:$O,Partidos!$C:$C,Partidos!$X$2,Partidos!$D:$D,B5)+SUMIFS(Partidos!$O:$O,Partidos!$C:$C,Partidos!$X$2,Partidos!$E:$E,B5)+SUMIFS(Partidos!$N:$N,Partidos!$C:$C,Partidos!$X$2,Partidos!$F:$F,B5)+SUMIFS(Partidos!$N:$N,Partidos!$C:$C,Partidos!$X$2,Partidos!$G:$G,B5)) -> 18 | M5: =IF(B5="","",K5-L5) -> 13
A6: =IF(B6="","",RANK(J6,$J$2:$J$61,0)+COUNTIFS($J$2:$J$61,J6,$H$2:$H$61,">"&H6)+COUNTIFS($J$2:$J$61,J6,$H$2:$H$61,H6,$M$2:$M$61,">"&M6)+COUNTIFS($J$2:$J$61,J6,$H$2:$H$61,H6,$M$2:$M$61,M6,$D$2:$D$61,">"&D6)+COUNTIFS($J$2:$J$61,J6,$H$2:$H$61,H6,$M$2:$M$61,M6,$D$2:$D$61,D6,$B$2:$B$61,">"&B6)) -> 5 | B6: =IF(Jugadores!B3="","",Jugadores!B3) -> Imobach González | C6: =IF(B6="","",COUNTIFS(Partidos!$C:$C,Partidos!$X$2,Partidos!$D:$D,B6)+COUNTIFS(Partidos!$C:$C,Partidos!$X$2,Partidos!$E:$E,B6)+COUNTIFS(Partidos!$C:$C,Partidos!$X$2,Partidos!$F:$F,B6)+COUNTIFS(Partidos!$C:$C,Partidos!$X$2,Partidos!$G:$G,B6)) -> 26 | D6: =IF(B6="","",COUNTIFS(Partidos!$C:$C,Partidos!$X$2,Partidos!$P:$P,"A",Partidos!$D:$D,B6)+COUNTIFS(Partidos!$C:$C,Partidos!$X$2,Partidos!$P:$P,"A",Partidos!$E:$E,B6)+COUNTIFS(Partidos!$C:$C,Partidos!$X$2,Partidos!$P:$P,"B",Partidos!$F:$F,B6)+COUNTIFS(Partidos!$C:$C,Partidos!$X$2,Partidos!$P:$P,"B",Partidos!$G:$G,B6)) -> 14 | E6: =IF(B6="","",C6-D6) -> 12 | F6: =IF(B6="","",SUMIFS(Partidos!$Q:$Q,Partidos!$C:$C,Partidos!$X$2,Partidos!$D:$D,B6)+SUMIFS(Partidos!$Q:$Q,Partidos!$C:$C,Partidos!$X$2,Partidos!$E:$E,B6)+SUMIFS(Partidos!$R:$R,Partidos!$C:$C,Partidos!$X$2,Partidos!$F:$F,B6)+SUMIFS(Partidos!$R:$R,Partidos!$C:$C,Partidos!$X$2,Partidos!$G:$G,B6)) -> 293 | G6: =IF(B6="","",SUMIFS(Partidos!$R:$R,Partidos!$C:$C,Partidos!$X$2,Partidos!$D:$D,B6)+SUMIFS(Partidos!$R:$R,Partidos!$C:$C,Partidos!$X$2,Partidos!$E:$E,B6)+SUMIFS(Partidos!$Q:$Q,Partidos!$C:$C,Partidos!$X$2,Partidos!$F:$F,B6)+SUMIFS(Partidos!$Q:$Q,Partidos!$C:$C,Partidos!$X$2,Partidos!$G:$G,B6)) -> 270 | H6: =IF(B6="","",F6-G6) -> 23 | I6: =IF(B6="","",SUMIFS(Partidos!$T:$T,Partidos!$C:$C,Partidos!$X$2,Partidos!$D:$D,B6)+SUMIFS(Partidos!$T:$T,Partidos!$C:$C,Partidos!$X$2,Partidos!$E:$E,B6)+SUMIFS(Partidos!$U:$U,Partidos!$C:$C,Partidos!$X$2,Partidos!$F:$F,B6)+SUMIFS(Partidos!$U:$U,Partidos!$C:$C,Partidos!$X$2,Partidos!$G:$G,B6)) -> 1.72 | J6: =IF(B6="","",D6*Partidos!$X$3 + E6*Partidos!$X$4 + I6) -> 29.72 | K6: =IF(B6="","",SUMIFS(Partidos!$N:$N,Partidos!$C:$C,Partidos!$X$2,Partidos!$D:$D,B6)+SUMIFS(Partidos!$N:$N,Partidos!$C:$C,Partidos!$X$2,Partidos!$E:$E,B6)+SUMIFS(Partidos!$O:$O,Partidos!$C:$C,Partidos!$X$2,Partidos!$F:$F,B6)+SUMIFS(Partidos!$O:$O,Partidos!$C:$C,Partidos!$X$2,Partidos!$G:$G,B6)) -> 33 | L6: =IF(B6="","",SUMIFS(Partidos!$O:$O,Partidos!$C:$C,Partidos!$X$2,Partidos!$D:$D,B6)+SUMIFS(Partidos!$O:$O,Partidos!$C:$C,Partidos!$X$2,Partidos!$E:$E,B6)+SUMIFS(Partidos!$N:$N,Partidos!$C:$C,Partidos!$X$2,Partidos!$F:$F,B6)+SUMIFS(Partidos!$N:$N,Partidos!$C:$C,Partidos!$X$2,Partidos!$G:$G,B6)) -> 27 | M6: =IF(B6="","",K6-L6) -> 6
A7: =IF(B7="","",RANK(J7,$J$2:$J$61,0)+COUNTIFS($J$2:$J$61,J7,$H$2:$H$61,">"&H7)+COUNTIFS($J$2:$J$61,J7,$H$2:$H$61,H7,$M$2:$M$61,">"&M7)+COUNTIFS($J$2:$J$61,J7,$H$2:$H$61,H7,$M$2:$M$61,M7,$D$2:$D$61,">"&D7)+COUNTIFS($J$2:$J$61,J7,$H$2:$H$61,H7,$M$2:$M$61,M7,$D$2:$D$61,D7,$B$2:$B$61,">"&B7)) -> 6 | B7: =IF(Jugadores!B13="","",Jugadores!B13) -> Guillermo Medina | C7: =IF(B7="","",COUNTIFS(Partidos!$C:$C,Partidos!$X$2,Partidos!$D:$D,B7)+COUNTIFS(Partidos!$C:$C,Partidos!$X$2,Partidos!$E:$E,B7)+COUNTIFS(Partidos!$C:$C,Partidos!$X$2,Partidos!$F:$F,B7)+COUNTIFS(Partidos!$C:$C,Partidos!$X$2,Partidos!$G:$G,B7)) -> 20 | D7: =IF(B7="","",COUNTIFS(Partidos!$C:$C,Partidos!$X$2,Partidos!$P:$P,"A",Partidos!$D:$D,B7)+COUNTIFS(Partidos!$C:$C,Partidos!$X$2,Partidos!$P:$P,"A",Partidos!$E:$E,B7)+COUNTIFS(Partidos!$C:$C,Partidos!$X$2,Partidos!$P:$P,"B",Partidos!$F:$F,B7)+COUNTIFS(Partidos!$C:$C,Partidos!$X$2,Partidos!$P:$P,"B",Partidos!$G:$G,B7)) -> 9 | E7: =IF(B7="","",C7-D7) -> 11 | F7: =IF(B7="","",SUMIFS(Partidos!$Q:$Q,Partidos!$C:$C,Partidos!$X$2,Partidos!$D:$D,B7)+SUMIFS(Partidos!$Q:$Q,Partidos!$C:$C,Partidos!$X$2,Partidos!$E:$E,B7)+SUMIFS(Partidos!$R:$R,Partidos!$C:$C,Partidos!$X$2,Partidos!$F:$F,B7)+SUMIFS(Partidos!$R:$R,Partidos!$C:$C,Partidos!$X$2,Partidos!$G:$G,B7)) -> 194 | G7: =IF(B7="","",SUMIFS(Partidos!$R:$R,Partidos!$C:$C,Partidos!$X$2,Partidos!$D:$D,B7)+SUMIFS(Partidos!$R:$R,Partidos!$C:$C,Partidos!$X$2,Partidos!$E:$E,B7)+SUMIFS(Partidos!$Q:$Q,Partidos!$C:$C,Partidos!$X$2,Partidos!$F:$F,B7)+SUMIFS(Partidos!$Q:$Q,Partidos!$C:$C,Partidos!$X$2,Partidos!$G:$G,B7)) -> 215 | H7: =IF(B7="","",F7-G7) -> -21 | I7: =IF(B7="","",SUMIFS(Partidos!$T:$T,Partidos!$C:$C,Partidos!$X$2,Partidos!$D:$D,B7)+SUMIFS(Partidos!$T:$T,Partidos!$C:$C,Partidos!$X$2,Partidos!$E:$E,B7)+SUMIFS(Partidos!$U:$U,Partidos!$C:$C,Partidos!$X$2,Partidos!$F:$F,B7)+SUMIFS(Partidos!$U:$U,Partidos!$C:$C,Partidos!$X$2,Partidos!$G:$G,B7)) -> 1 | J7: =IF(B7="","",D7*Partidos!$X$3 + E7*Partidos!$X$4 + I7) -> 19 | K7: =IF(B7="","",SUMIFS(Partidos!$N:$N,Partidos!$C:$C,Partidos!$X$2,Partidos!$D:$D,B7)+SUMIFS(Partidos!$N:$N,Partidos!$C:$C,Partidos!$X$2,Partidos!$E:$E,B7)+SUMIFS(Partidos!$O:$O,Partidos!$C:$C,Partidos!$X$2,Partidos!$F:$F,B7)+SUMIFS(Partidos!$O:$O,Partidos!$C:$C,Partidos!$X$2,Partidos!$G:$G,B7)) -> 22 | L7: =IF(B7="","",SUMIFS(Partidos!$O:$O,Partidos!$C:$C,Partidos!$X$2,Partidos!$D:$D,B7)+SUMIFS(Partidos!$O:$O,Partidos!$C:$C,Partidos!$X$2,Partidos!$E:$E,B7)+SUMIFS(Partidos!$N:$N,Partidos!$C:$C,Partidos!$X$2,Partidos!$F:$F,B7)+SUMIFS(Partidos!$N:$N,Partidos!$C:$C,Partidos!$X$2,Partidos!$G:$G,B7)) -> 25 | M7: =IF(B7="","",K7-L7) -> -3
A8: =IF(B8="","",RANK(J8,$J$2:$J$61,0)+COUNTIFS($J$2:$J$61,J8,$H$2:$H$61,">"&H8)+COUNTIFS($J$2:$J$61,J8,$H$2:$H$61,H8,$M$2:$M$61,">"&M8)+COUNTIFS($J$2:$J$61,J8,$H$2:$H$61,H8,$M$2:$M$61,M8,$D$2:$D$61,">"&D8)+COUNTIFS($J$2:$J$61,J8,$H$2:$H$61,H8,$M$2:$M$61,M8,$D$2:$D$61,D8,$B$2:$B$61,">"&B8)) -> 7 | B8: =IF(Jugadores!B15="","",Jugadores!B15) -> Nacho Navidad | C8: =IF(B8="","",COUNTIFS(Partidos!$C:$C,Partidos!$X$2,Partidos!$D:$D,B8)+COUNTIFS(Partidos!$C:$C,Partidos!$X$2,Partidos!$E:$E,B8)+COUNTIFS(Partidos!$C:$C,Partidos!$X$2,Partidos!$F:$F,B8)+COUNTIFS(Partidos!$C:$C,Partidos!$X$2,Partidos!$G:$G,B8)) -> 25 | D8: =IF(B8="","",COUNTIFS(Partidos!$C:$C,Partidos!$X$2,Partidos!$P:$P,"A",Partidos!$D:$D,B8)+COUNTIFS(Partidos!$C:$C,Partidos!$X$2,Partidos!$P:$P,"A",Partidos!$E:$E,B8)+COUNTIFS(Partidos!$C:$C,Partidos!$X$2,Partidos!$P:$P,"B",Partidos!$F:$F,B8)+COUNTIFS(Partidos!$C:$C,Partidos!$X$2,Partidos!$P:$P,"B",Partidos!$G:$G,B8)) -> 8 | E8: =IF(B8="","",C8-D8) -> 17 | F8: =IF(B8="","",SUMIFS(Partidos!$Q:$Q,Partidos!$C:$C,Partidos!$X$2,Partidos!$D:$D,B8)+SUMIFS(Partidos!$Q:$Q,Partidos!$C:$C,Partidos!$X$2,Partidos!$E:$E,B8)+SUMIFS(Partidos!$R:$R,Partidos!$C:$C,Partidos!$X$2,Partidos!$F:$F,B8)+SUMIFS(Partidos!$R:$R,Partidos!$C:$C,Partidos!$X$2,Partidos!$G:$G,B8)) -> 239 | G8: =IF(B8="","",SUMIFS(Partidos!$R:$R,Partidos!$C:$C,Partidos!$X$2,Partidos!$D:$D,B8)+SUMIFS(Partidos!$R:$R,Partidos!$C:$C,Partidos!$X$2,Partidos!$E:$E,B8)+SUMIFS(Partidos!$Q:$Q,Partidos!$C:$C,Partidos!$X$2,Partidos!$F:$F,B8)+SUMIFS(Partidos!$Q:$Q,Partidos!$C:$C,Partidos!$X$2,Partidos!$G:$G,B8)) -> 288 | H8: =IF(B8="","",F8-G8) -> -49 | I8: =IF(B8="","",SUMIFS(Partidos!$T:$T,Partidos!$C:$C,Partidos!$X$2,Partidos!$D:$D,B8)+SUMIFS(Partidos!$T:$T,Partidos!$C:$C,Partidos!$X$2,Partidos!$E:$E,B8)+SUMIFS(Partidos!$U:$U,Partidos!$C:$C,Partidos!$X$2,Partidos!$F:$F,B8)+SUMIFS(Partidos!$U:$U,Partidos!$C:$C,Partidos!$X$2,Partidos!$G:$G,B8)) -> 0.9 | J8: =IF(B8="","",D8*Partidos!$X$3 + E8*Partidos!$X$4 + I8) -> 16.9 | K8: =IF(B8="","",SUMIFS(Partidos!$N:$N,Partidos!$C:$C,Partidos!$X$2,Partidos!$D:$D,B8)+SUMIFS(Partidos!$N:$N,Partidos!$C:$C,Partidos!$X$2,Partidos!$E:$E,B8)+SUMIFS(Partidos!$O:$O,Partidos!$C:$C,Partidos!$X$2,Partidos!$F:$F,B8)+SUMIFS(Partidos!$O:$O,Partidos!$C:$C,Partidos!$X$2,Partidos!$G:$G,B8)) -> 20 | L8: =IF(B8="","",SUMIFS(Partidos!$O:$O,Partidos!$C:$C,Partidos!$X$2,Partidos!$D:$D,B8)+SUMIFS(Partidos!$O:$O,Partidos!$C:$C,Partidos!$X$2,Partidos!$E:$E,B8)+SUMIFS(Partidos!$N:$N,Partidos!$C:$C,Partidos!$X$2,Partidos!$F:$F,B8)+SUMIFS(Partidos!$N:$N,Partidos!$C:$C,Partidos!$X$2,Partidos!$G:$G,B8)) -> 37 | M8: =IF(B8="","",K8-L8) -> -17
A9: =IF(B9="","",RANK(J9,$J$2:$J$61,0)+COUNTIFS($J$2:$J$61,J9,$H$2:$H$61,">"&H9)+COUNTIFS($J$2:$J$61,J9,$H$2:$H$61,H9,$M$2:$M$61,">"&M9)+COUNTIFS($J$2:$J$61,J9,$H$2:$H$61,H9,$M$2:$M$61,M9,$D$2:$D$61,">"&D9)+COUNTIFS($J$2:$J$61,J9,$H$2:$H$61,H9,$M$2:$M$61,M9,$D$2:$D$61,D9,$B$2:$B$61,">"&B9)) -> 8 | B9: =IF(Jugadores!B9="","",Jugadores!B9) -> Alberto Pulido | C9: =IF(B9="","",COUNTIFS(Partidos!$C:$C,Partidos!$X$2,Partidos!$D:$D,B9)+COUNTIFS(Partidos!$C:$C,Partidos!$X$2,Partidos!$E:$E,B9)+COUNTIFS(Partidos!$C:$C,Partidos!$X$2,Partidos!$F:$F,B9)+COUNTIFS(Partidos!$C:$C,Partidos!$X$2,Partidos!$G:$G,B9)) -> 14 | D9: =IF(B9="","",COUNTIFS(Partidos!$C:$C,Partidos!$X$2,Partidos!$P:$P,"A",Partidos!$D:$D,B9)+COUNTIFS(Partidos!$C:$C,Partidos!$X$2,Partidos!$P:$P,"A",Partidos!$E:$E,B9)+COUNTIFS(Partidos!$C:$C,Partidos!$X$2,Partidos!$P:$P,"B",Partidos!$F:$F,B9)+COUNTIFS(Partidos!$C:$C,Partidos!$X$2,Partidos!$P:$P,"B",Partidos!$G:$G,B9)) -> 7 | E9: =IF(B9="","",C9-D9) -> 7 | F9: =IF(B9="","",SUMIFS(Partidos!$Q:$Q,Partidos!$C:$C,Partidos!$X$2,Partidos!$D:$D,B9)+SUMIFS(Partidos!$Q:$Q,Partidos!$C:$C,Partidos!$X$2,Partidos!$E:$E,B9)+SUMIFS(Partidos!$R:$R,Partidos!$C:$C,Partidos!$X$2,Partidos!$F:$F,B9)+SUMIFS(Partidos!$R:$R,Partidos!$C:$C,Partidos!$X$2,Partidos!$G:$G,B9)) -> 152 | G9: =IF(B9="","",SUMIFS(Partidos!$R:$R,Partidos!$C:$C,Partidos!$X$2,Partidos!$D:$D,B9)+SUMIFS(Partidos!$R:$R,Partidos!$C:$C,Partidos!$X$2,Partidos!$E:$E,B9)+SUMIFS(Partidos!$Q:$Q,Partidos!$C:$C,Partidos!$X$2,Partidos!$F:$F,B9)+SUMIFS(Partidos!$Q:$Q,Partidos!$C:$C,Partidos!$X$2,Partidos!$G:$G,B9)) -> 148 | H9: =IF(B9="","",F9-G9) -> 4 | I9: =IF(B9="","",SUMIFS(Partidos!$T:$T,Partidos!$C:$C,Partidos!$X$2,Partidos!$D:$D,B9)+SUMIFS(Partidos!$T:$T,Partidos!$C:$C,Partidos!$X$2,Partidos!$E:$E,B9)+SUMIFS(Partidos!$U:$U,Partidos!$C:$C,Partidos!$X$2,Partidos!$F:$F,B9)+SUMIFS(Partidos!$U:$U,Partidos!$C:$C,Partidos!$X$2,Partidos!$G:$G,B9)) -> 0.84 | J9: =IF(B9="","",D9*Partidos!$X$3 + E9*Partidos!$X$4 + I9) -> 14.84 | K9: =IF(B9="","",SUMIFS(Partidos!$N:$N,Partidos!$C:$C,Partidos!$X$2,Partidos!$D:$D,B9)+SUMIFS(Partidos!$N:$N,Partidos!$C:$C,Partidos!$X$2,Partidos!$E:$E,B9)+SUMIFS(Partidos!$O:$O,Partidos!$C:$C,Partidos!$X$2,Partidos!$F:$F,B9)+SUMIFS(Partidos!$O:$O,Partidos!$C:$C,Partidos!$X$2,Partidos!$G:$G,B9)) -> 16 | L9: =IF(B9="","",SUMIFS(Partidos!$O:$O,Partidos!$C:$C,Partidos!$X$2,Partidos!$D:$D,B9)+SUMIFS(Partidos!$O:$O,Partidos!$C:$C,Partidos!$X$2,Partidos!$E:$E,B9)+SUMIFS(Partidos!$N:$N,Partidos!$C:$C,Partidos!$X$2,Partidos!$F:$F,B9)+SUMIFS(Partidos!$N:$N,Partidos!$C:$C,Partidos!$X$2,Partidos!$G:$G,B9)) -> 18 | M9: =IF(B9="","",K9-L9) -> -2
